Workbook
Name ADDS_AUS: 0.4937
Name ADDS_MTL: 0.39
Name ADDS_SIN: 0.5834
Name ADDS_STG: 0.42
Name BE006K: 700
Name BE010K: 600
Name BT074K: 100
Name BT369K: 100
Name COUNTER: 6
Name CTL.ORDERINGSTATE: 0
Name EXCH_AUD: 1.446
Name EXCH_CAD: 1.3167
Name EXCH_CLP: 626.8
Name EXCH_SGD: 1.7069
Name IN: '[23]Instru Correa'!$AH$9
Name INDIMES: {#N/A,#N/A,FALSE,"Costos_Elem_Hid";#N/A,#N/A,FALSE,"Costos_Elem_Hid";#N/A,#N/A,FALSE,"Costos_Elem_Hid"}
Name initialWorkingCapital: 0
Name IPC_E: [24]Inversiones!$D$718
Name IPC_N: [24]Inversiones!$D$717
Name lbsPerTon: 2204.6
Name Materiales_2004_Consulta: [25]Materiales_2004_Consulta!$A$3:$Q$203
Name MB_24A25: (108.2/103.15)
Name MESES_05: '[26]CTOS. ORIG.'!$C$5:$N$5
Name MESES_06: '[26]CTOS. ORIG.'!$O$5:$Z$5
Name MESESGANTT: [26]Gantt!$F$55:$U$55
Name modelStartDate: 33604
Name no: 0
Name Numero_Unidades_Funcionales: [27]Constantes!$C$54
Name oreProductionDaily: 26640
Name Plazo_Obra: [27]Constantes!$C$58
Name Plus_No_Remunerativo: [28]Constantes!$C$45
Name preProductionDurationMonths: 2
Name PRODUCTIVIDAD: [29]DOTACION_CBV99!$A$67:$AA$135
Name RANTOT: [30]TABLAS!$R$105:$AE$200
Name riskATSToutputStatistic: 4
Name RiskAutoStopPercChange: 1.5
Name RiskExcelReportsToGenerate: 32
Name RiskReportGraphFormat: 0
Name RiskResultsUpdateFreq: 100
Name RiskStatFunctionsUpdateFreq: 1
Name RPTC: '[23]Instru Correa'!$AD$9
Name shiftPeriodConversion: 0.36
Name sí: 1
Name STOCK: '[23]Instru Correa'!$AE$9
Name taxRate: 0.5
Name TC: 920
Name TC_AUS: 650
Name TC_CAD: 693
Name TC_CAD: 693
Name TC_CAD: 693
Name TC_CAD: 681
Name TComp: '[35]Tabla Comparativa'!$B$2:$I$23
Name TopRankOnlyInputsChangeThreshold: 0.01
Name UF: 40000
Name ujuu: 1000
Name vvvvv: [38]TE2GEFUND_MES!$B$8:$E$154
Name wageEscalation: 0.02

Sheet R. Actividades
B1: Registro de actividades M24G005
B2: Etapa | C2: Actividad | D2: Comentario | E2: Proveedor | F2: Fecha Incio | G2: Fecha fin | H2: ESTATUS
B3: Monitoreo y búsqueda de nuevas oportunidades | C3: Participación congresos y otros (PDAC) | D3: PDAC: 3 internos 3 viajes | F3: 46082 | G3: 46082 | H3: Pendiente
B4: Monitoreo y búsqueda de nuevas oportunidades | C4: Terreno proyectos Canadá | D4: 25 días: JR-SC-AA + consultor (darren) 3 viajes | F4: 46174 | G4: 46174 | H4: Pendiente
B5: Monitoreo y búsqueda de nuevas oportunidades | C5: Evaluación oportunidades + firma NDA Canadá | D5: RRM proyecto corto | F5: 46266 | G5: 46266 | H5: Pendiente
B6: Monitoreo y búsqueda de nuevas oportunidades | C6: Evaluación oportunidades + firma NDA Australia | D6: RRM proyecto corto | F6: 46174 | G6: 46174 | H6: Pendiente
B7: Seguimiento proyecto 1 | C7: Terreno proyectos USA | F7: 46054 | G7: 46054 | H7: Pendiente
B8: Seguimiento proyecto 1 | C8: Análisis y recomendaciones proy. USA | F8: 46082 | G8: 46082 | H8: Pendiente

Sheet Form. Cochilco RealProyectado
B2: API M24G005 - FORMATO COCHILCO
B4: API | C4: NOMBRE | D4: 2024 | E4: 2025 | F4: 2026 | G4: 2027 | H4: 2028 | I4: TOTAL US$ | L4: M Nac | M4: M Ext
L5: 1.0336488 | M5: 1.0237726
B6: M24G005 | C6: Exploración Internacional Otros Países | D6: =SUM(D7) -> 228189.96 | E6: =SUM(E7) -> 476667.45 | F6: =SUM(F7) -> 1674600.4 | G6: =SUM(G7) -> 2034249.7 | H6: =SUM(H7) -> 2331209 | I6: =SUM(I7) -> 6744916.6
B7: M24G005-1.1 | C7: E. Internacional Otros Países | D7: =SUM(D8:D9) -> 228189.96 | E7: =SUM(E8:E9) -> 476667.45 | F7: =SUM(F8:F9) -> 1674600.4 | G7: =SUM(G8:G9) -> 2034249.7 | H7: =SUM(H8:H9) -> 2331209 | I7: =SUM(I8:I9) -> 6744916.6
B8: M24G005-1.1.1 | C8: Metalotectos de Interés Item I | D8: ='Formato SAP'!G6 -> 228189.96 | E8: ='Formato SAP'!I6 -> 127558.07 | F8: ='Formato SAP'!K6 -> 0 | G8: ='Formato SAP'!M6 -> 0 | H8: ='Formato SAP'!O6 -> 0 | I8: =SUM(D8:H8) -> 355748.03 | L8: =+#REF!*L5 -> #REF! | M8: =+(#REF!-#REF!)*M5 -> #REF! | N8: =+M8+L8 -> #REF!
B9: M24G005-1.1.2 | C9: Metalotectos de Interés Item II | D9: ='Formato SAP'!G22 -> 0 | E9: ='Formato SAP'!I22 -> 349109.38 | F9: ='Formato SAP'!K22 -> 1674600.4 | G9: ='Formato SAP'!M22 -> 2034249.7 | H9: ='Formato SAP'!O22 -> 2331209 | I9: =SUM(D9:H9) -> 6389168.5 | L9: =+#REF!*L6 -> #REF! | M9: =+(#REF!-#REF!)*M6 -> #REF! | N9: =+M9+L9 -> #REF!

Sheet formato sap original 
E2: 2024-2027 | F2: 2024-2027 | I2: 2024 | K2: 2025 | M2: 2026 | O2: 2027 | Q2: PLANIFICACION AÑO 2024 | AD2: PLANIFICACION AÑO 2025 | AQ2: PLANIFICACION AÑO 2026 | BD2: PLANIFICACION AÑO 2027
E3: TOTAL | F3: TOTAL | I3: TOTAL AÑO | K3: TOTAL AÑO | M3: TOTAL AÑO | O3: TOTAL AÑO | Q3: 45322 | R3: 45351 | S3: 45382 | T3: 45412 | U3: 45443 | V3: 45473 | W3: 45504 | X3: 45535 | Y3: 45565 | Z3: 45596 | AA3: 45626 | AB3: 45657 | AD3: 45688 | AE3: 45716 | AF3: 45747 | AG3: 45777 | AH3: 45808 | AI3: 45838 | AJ3: 45869 | AK3: 45900 | AL3: 45930 | AM3: 45961 | AN3: 45991 | AO3: 46022 | AQ3: 46053 | AR3: 46081 | AS3: 46112 | AT3: 46142 | AU3: 46173 | AV3: 46203 | AW3: 46234 | AX3: 46265 | AY3: 46295 | AZ3: 46326 | BA3: 46356 | BB3: 46387 | BD3: 46053 | BE3: 46081 | BF3: 46112 | BG3: 46142 | BH3: 46173 | BI3: 46203 | BJ3: 46234 | BK3: 46265 | BL3: 46295 | BM3: 46326 | BN3: 46356 | BO3: 46387
C4: Exploración Internacional Otros Países | E4: 6571392.7 | F4: =F5 -> 6567358 | G4: =G5 -> 6692580.5 | I4: 655490.84 | K4: 1998016.6 | M4: 1999923.5 | O4: 1917961.8 | Q4: 0 | R4: 0 | S4: 0 | T4: 0 | U4: 0 | V4: 0 | W4: 0 | X4: 230144.25 | Y4: 65585.624 | Z4: 254411.09 | AA4: 61027.5 | AB4: 44322.382 | AD4: 69996.621 | AE4: 36799.149 | AF4: 73509.501 | AG4: 144894.91 | AH4: 0 | AI4: 0 | AJ4: 0 | AK4: 0 | AL4: 0 | AM4: 0 | AN4: 0 | AO4: 0 | AQ4: 0 | AR4: 0 | AS4: 0 | AT4: 0 | AU4: 0 | AV4: 0 | AW4: 0 | AX4: 0 | AY4: 0 | AZ4: 0 | BA4: 0 | BB4: 0 | BD4: 0 | BE4: 0 | BF4: 0 | BG4: 0 | BH4: 0 | BI4: 0 | BJ4: 0 | BK4: 0 | BL4: 0 | BM4: 0 | BN4: 0 | BO4: 0
C5: E. Internacional Otros Países | E5: 6571392.7 | F5: =F6+F22 -> 6567358 | G5: =G6+G22 -> 6692580.5 | I5: 655490.84 | K5: 1998016.6 | M5: 1999923.5 | O5: 1917961.8 | Q5: 0 | R5: 0 | S5: 0 | T5: 0 | U5: 0 | V5: 0 | W5: 0 | X5: 230144.25 | Y5: 65585.624 | Z5: 254411.09 | AA5: 61027.5 | AB5: 44322.382 | AD5: 69996.621 | AE5: 36799.149 | AF5: 73509.501 | AG5: 144894.91 | AH5: 0 | AI5: 0 | AJ5: 0 | AK5: 0 | AL5: 0 | AM5: 0 | AN5: 0 | AO5: 0 | AQ5: 0 | AR5: 0 | AS5: 0 | AT5: 0 | AU5: 0 | AV5: 0 | AW5: 0 | AX5: 0 | AY5: 0 | AZ5: 0 | BA5: 0 | BB5: 0 | BD5: 0 | BE5: 0 | BF5: 0 | BG5: 0 | BH5: 0 | BI5: 0 | BJ5: 0 | BK5: 0 | BL5: 0 | BM5: 0 | BN5: 0 | BO5: 0
C6: Metalotectos de Interés Item I | E6: 861309.8 | F6: 367893.41 | G6: =SUM(G7:G21) -> 368944.88 | I6: 655490.84 | K6: 205818.96 | M6: 0 | O6: 0 | Q6: 0 | R6: 0 | S6: 0 | T6: 0 | U6: 0 | V6: 0 | W6: 0 | X6: 230144.25 | Y6: 65585.624 | Z6: 254411.09 | AA6: 61027.5 | AB6: 44322.382 | AD6: 36799.149 | AE6: 36799.149 | AF6: 36799.149 | AG6: 95421.518 | AH6: 0 | AI6: 0 | AJ6: 0 | AK6: 0 | AL6: 0 | AM6: 0 | AN6: 0 | AO6: 0 | AQ6: 0 | AR6: 0 | AS6: 0 | AT6: 0 | AU6: 0 | AV6: 0 | AW6: 0 | AX6: 0 | AY6: 0 | AZ6: 0 | BA6: 0 | BB6: 0 | BD6: 0 | BE6: 0 | BF6: 0 | BG6: 0 | BH6: 0 | BI6: 0 | BJ6: 0 | BK6: 0 | BL6: 0 | BM6: 0 | BN6: 0 | BO6: 0
C7: Geología MN | D7: 91243110 | E7: 311221.55 | F7: 260912.23 | G7: =F7*$E$51 -> 260155.53 | I7: 171711.94 | K7: 139509.62 | M7: 0 | O7: 0 | X7: 29286.014 | Y7: 16866.007 | Z7: 44758.215 | AA7: 38793.948 | AB7: 42007.754 | AD7: 34877.404 | AE7: 34877.404 | AF7: 34877.404 | AG7: 34877.404
C8: Geología ME | D8: 91243120 | E8: 181824 | F8: 71122.181 | G8: =F8*$F$51 -> 73083.421 | I8: 181824 | K8: 0 | M8: 0 | O8: 0 | X8: 67366 | Y8: 15546 | Z8: 88314.286 | AA8: 10597.714 | AB8: 0
C9: Geoquímica ME | D9: 91243220 | E9: 0 | F9: 0 | G9: =F9*$F$51 -> 0 | I9: 0 | K9: 0 | M9: 0 | O9: 0 | X9: 0 | Y9: 0 | Z9: 0 | AA9: 0 | AB9: 0
C10: Geofísica ME | D10: 91243310 | E10: 0 | F10: 0 | G10: =F10*$F$51 -> 0 | I10: 0 | K10: 0 | M10: 0 | O10: 0 | X10: 0 | Y10: 0 | Z10: 0 | AA10: 0 | AB10: 0
C11: Sondajes ME | D11: 91243510 | E11: 0 | F11: 0 | G11: =F11*$F$51 -> 0 | I11: 0 | K11: 0 | M11: 0 | O11: 0 | X11: 0 | Y11: 0 | Z11: 0 | AA11: 0 | AB11: 0
C12: Logística MN | D12: 91243520 | E12: 144957.87 | F12: 20598.61 | G12: =F12*$E$51 -> 20538.87 | I12: 144957.87 | K12: 0 | M12: 0 | O12: 0 | X12: 71228.697 | Y12: 325.08514 | Z12: 68390.392 | AA12: 5013.6988 | AB12: 0
C13: Logística ME | D13: 91243530 | E13: 137937.38 | F13: -1610.0539 | G13: =F13*$F$51 -> -1654.4522 | I13: 137937.38 | K13: 0 | M13: 0 | O13: 0 | X13: 56674.054 | Y13: 30770.7 | Z13: 46479.522 | AA13: 4013.1024 | AB13: 0
C14: Propiedad Minera ME | D14: 91243610 | E14: 0 | F14: 0 | G14: =F14*$F$51 -> 0 | I14: 0 | K14: 0 | M14: 0 | O14: 0 | X14: 0 | Y14: 0 | Z14: 0 | AA14: 0 | AB14: 0
C15: Medio Ambiente MN | D15: 91243620 | E15: 0 | F15: 0 | G15: =F15*$E$51 -> 0 | I15: 0 | K15: 0 | M15: 0 | O15: 0 | X15: 0 | Y15: 0 | Z15: 0 | AA15: 0 | AB15: 0
C16: Medio Ambiente ME | D16: 91243630 | E16: 0 | F16: 0 | G16: =F16*$F$51 -> 0 | I16: 0 | K16: 0 | M16: 0 | O16: 0 | X16: 0 | Y16: 0 | Z16: 0 | AA16: 0 | AB16: 0
C17: Seguridad ME | D17: 91243640 | E17: 0 | F17: 0 | G17: =F17*$F$51 -> 0 | I17: 0 | K17: 0 | M17: 0 | O17: 0 | X17: 0 | Y17: 0 | Z17: 0 | AA17: 0 | AB17: 0
C18: Comunidades ME | D18: 91243650 | E18: 0 | F18: 0 | G18: =F18*$F$51 -> 0 | I18: 0 | K18: 0 | M18: 0 | O18: 0 | X18: 0 | Y18: 0 | Z18: 0 | AA18: 0 | AB18: 0
C19: Administración MN | D19: 91243660 | E19: 0 | F19: 3012.3191 | G19: =F19*$E$51 -> 3003.5827 | I19: 0 | K19: 0 | M19: 0 | O19: 0 | X19: 0 | Y19: 0 | Z19: 0 | AA19: 0 | AB19: 0
C20: Contingencia ME | D20: 91243750 | E20: 58622.369 | F20: 0 | G20: =F20*$F$51 -> 0 | I20: 0 | K20: 58622.369 | M20: 0 | O20: 0 | X20: 0 | Y20: 0 | Z20: 0 | AA20: 0 | AB20: 0 | AG20: 58622.369
C21: Fee MN | D21: 91243910 | E21: 26746.631 | F21: 13858.122 | G21: =F21*$E$51 -> 13817.931 | I21: 19059.651 | K21: 7686.9798 | M21: 0 | O21: 0 | X21: 5589.4831 | Y21: 2077.8328 | Z21: 6468.6709 | AA21: 2609.0371 | AB21: 2314.6273 | AD21: 1921.745 | AE21: 1921.745 | AF21: 1921.745 | AG21: 1921.745
C22: Metalotectos de Interés Item II | E22: 5710082.9 | F22: =SUM(F23:F37) -> 6199464.6 | G22: =SUM(G23:G37) -> 6323635.6 | I22: 0 | K22: 1792197.7 | M22: 1999923.5 | O22: 1917961.8 | Q22: 0 | R22: 0 | S22: 0 | T22: 0 | U22: 0 | V22: 0 | W22: 0 | X22: 0 | Y22: 0 | Z22: 0 | AA22: 0 | AB22: 0 | AD22: 33197.472 | AE22: 0 | AF22: 36710.352 | AG22: 49473.394 | AH22: 282718.02 | AI22: 819846.4 | AJ22: 214169.88 | AK22: 109794.44 | AL22: 65622.678 | AM22: 99543.501 | AN22: 36799.149 | AO22: 44322.382 | AQ22: 13718.836 | AR22: 13718.836 | AS22: 373078.04 | AT22: 665606.68 | AU22: 331598.57 | AV22: 321344.39 | AW22: 17340.332 | AX22: 17340.332 | AY22: 37223.509 | AZ22: 13718.836 | BA22: 13718.836 | BB22: 181516.3 | BD22: 1530718.8 | BE22: 139236.08 | BF22: 221199.63 | BG22: 26807.203 | BH22: 0 | BI22: 0 | BJ22: 0 | BK22: 0 | BL22: 0 | BM22: 0 | BN22: 0 | BO22: 0
C23: Geología MN | D23: 91243110 | E23: 489204.74 | F23: 1204379.7 | G23: =F23*$E$51 -> 1200886.7 | I23: 0 | K23: 294588.11 | M23: 156028.85 | O23: 38587.779 | AG23: 1194.5701 | AH23: 34955.082 | AI23: 27329.242 | AJ23: 49591.849 | AK23: 34877.404 | AL23: 34877.404 | AM23: 34877.404 | AN23: 34877.404 | AO23: 42007.754 | AQ23: 13002.404 | AR23: 13002.404 | AS23: 13002.404 | AT23: 13002.404 | AU23: 13002.404 | AV23: 13002.404 | AW23: 13002.404 | AX23: 13002.404 | AY23: 13002.404 | AZ23: 13002.404 | BA23: 13002.404 | BB23: 13002.404 | BD23: 13002.404 | BE23: 13002.404 | BF23: 12582.971 | BG23: 0
C24: Geología ME | D24: 91243120 | E24: 233024 | F24: 1301131.7 | G24: =F24*$F$51 -> 1337011.2 | I24: 0 | K24: 233024 | M24: 0 | O24: 0 | AD24: 0 | AE24: 0 | AF24: 0 | AG24: 6769.2308 | AH24: 93742.769 | AI24: 54128 | AJ24: 78384 | AK24: 0 | AL24: 0 | AM24: 0 | AN24: 0 | AO24: 0 | AQ24: 0 | AR24: 0 | AS24: 0 | AT24: 0 | AU24: 0 | AV24: 0 | AW24: 0 | AX24: 0 | AY24: 0 | AZ24: 0 | BA24: 0 | BB24: 0 | BD24: 0 | BE24: 0 | BF24: 0 | BG24: 0
C25: Geoquímica ME | D25: 91243220 | E25: 0 | F25: 0 | G25: =F25*$F$51 -> 0 | I25: 0 | K25: 0 | M25: 0 | O25: 0 | AD25: 0 | AE25: 0 | AF25: 0 | AG25: 0 | AH25: 0 | AI25: 0 | AJ25: 0 | AK25: 0 | AL25: 0 | AM25: 0 | AN25: 0 | AO25: 0 | AQ25: 0 | AR25: 0 | AS25: 0 | AT25: 0 | AU25: 0 | AV25: 0 | AW25: 0 | AX25: 0 | AY25: 0 | AZ25: 0 | BA25: 0 | BB25: 0 | BD25: 0 | BE25: 0 | BF25: 0 | BG25: 0
C26: Geofísica ME | D26: 91243310 | E26: 1650000 | F26: 1657397.3 | G26: =F26*$F$51 -> 1703101.1 | I26: 0 | K26: 0 | M26: 1050000 | O26: 600000 | AD26: 0 | AE26: 0 | AF26: 0 | AG26: 0 | AH26: 0 | AI26: 0 | AJ26: 0 | AK26: 0 | AL26: 0 | AM26: 0 | AN26: 0 | AO26: 0 | AQ26: 0 | AR26: 0 | AS26: 0 | AT26: 296703.3 | AU26: 306593.41 | AV26: 296703.3 | AW26: 0 | AX26: 0 | AY26: 0 | AZ26: 0 | BA26: 0 | BB26: 150000 | BD26: 600000 | BE26: 0 | BF26: 0 | BG26: 0
C27: Sondajes ME | D27: 91243510 | E27: 880000 | F27: 884062.6 | G27: =F27*$F$51 -> 908441.2 | I27: 0 | K27: 0 | M27: 0 | O27: 880000 | AD27: 0 | AE27: 0 | AF27: 0 | AG27: 0 | AH27: 0 | AI27: 0 | AJ27: 0 | AK27: 0 | AL27: 0 | AM27: 0 | AN27: 0 | AO27: 0 | AQ27: 0 | AR27: 0 | AS27: 0 | AT27: 0 | AU27: 0 | AV27: 0 | AW27: 0 | AX27: 0 | AY27: 0 | AZ27: 0 | BA27: 0 | BB27: 0 | BD27: 880000 | BE27: 0 | BF27: 0 | BG27: 0
C28: Logística MN | D28: 91243520 | E28: 260785.11 | F28: 226848.59 | G28: =F28*$E$51 -> 226190.68 | I28: 0 | K28: 260785.11 | M28: 0 | O28: 0 | AD28: 33197.472 | AE28: 0 | AF28: 36710.352 | AG28: 0 | AH28: 45704.485 | AI28: 10259.199 | AJ28: 30777.597 | AK28: 52068 | AL28: 0 | AM28: 52068 | AN28: 0 | AO28: 0 | AQ28: 0 | AR28: 0 | AS28: 0 | AT28: 0 | AU28: 0 | AV28: 0 | AW28: 0 | AX28: 0 | AY28: 0 | AZ28: 0 | BA28: 0 | BB28: 0 | BD28: 0 | BE28: 0 | BF28: 0 | BG28: 0
C29: Logística ME | D29: 91243530 | E29: 170117.15 | F29: 200867.5 | G29: =F29*$F$51 -> 206406.55 | I29: 0 | K29: 170117.15 | M29: 0 | O29: 0 | AD29: 0 | AE29: 0 | AF29: 0 | AG29: 0 | AH29: 91645.702 | AI29: 15991.897 | AJ29: 39993.563 | AK29: 11809.64 | AL29: 0 | AM29: 10676.352 | AN29: 0 | AO29: 0 | AQ29: 0 | AR29: 0 | AS29: 0 | AT29: 0 | AU29: 0 | AV29: 0 | AW29: 0 | AX29: 0 | AY29: 0 | AZ29: 0 | BA29: 0 | BB29: 0 | BD29: 0 | BE29: 0 | BF29: 0 | BG29: 0
C30: Propiedad Minera ME | D30: 91243610 | E30: 1700000 | F30: 331549.75 | G30: =F30*$F$51 -> 340692.45 | I30: 0 | K30: 720000 | M30: 720000 | O30: 260000 | AD30: 0 | AE30: 0 | AF30: 0 | AG30: 0 | AH30: 0 | AI30: 700000 | AJ30: 0 | AK30: 0 | AL30: 20000 | AM30: 0 | AN30: 0 | AO30: 0 | AQ30: 0 | AR30: 0 | AS30: 355737.7 | AT30: 344262.3 | AU30: 0 | AV30: 0 | AW30: 0 | AX30: 0 | AY30: 20000 | AZ30: 0 | BA30: 0 | BB30: 0 | BD30: 0 | BE30: 125517.24 | BF30: 134482.76 | BG30: 0
C31: Medio Ambiente MN | D31: 91243620 | E31: 0 | F31: 0 | G31: =F31*$E$51 -> 0 | I31: 0 | K31: 0 | M31: 0 | O31: 0 | AD31: 0 | AE31: 0 | AF31: 0 | AG31: 0 | AH31: 0 | AI31: 0 | AJ31: 0 | AK31: 0 | AL31: 0 | AM31: 0 | AN31: 0 | AO31: 0 | AQ31: 0 | AR31: 0 | AS31: 0 | AT31: 0 | AU31: 0 | AV31: 0 | AW31: 0 | AX31: 0 | AY31: 0 | AZ31: 0 | BA31: 0 | BB31: 0 | BD31: 0 | BE31: 0 | BF31: 0 | BG31: 0
C32: Medio Ambiente ME | D32: 91243630 | E32: 70000 | F32: 70323.079 | G32: =F32*$F$51 -> 72262.283 | I32: 0 | K32: 45000 | M32: 25000 | O32: 0 | AD32: 0 | AE32: 0 | AF32: 0 | AG32: 0 | AH32: 9117.6471 | AI32: 8823.5294 | AJ32: 9117.6471 | AK32: 9117.6471 | AL32: 8823.5294 | AM32: 0 | AN32: 0 | AO32: 0 | AQ32: 0 | AR32: 0 | AS32: 3621.4953 | AT32: 3504.6729 | AU32: 3621.4953 | AV32: 3504.6729 | AW32: 3621.4953 | AX32: 3621.4953 | AY32: 3504.6729 | AZ32: 0 | BA32: 0 | BB32: 0 | BD32: 0 | BE32: 0 | BF32: 0 | BG32: 0
C33: Seguridad ME | D33: 91243640 | E33: 0 | F33: 0 | G33: =F33*$F$51 -> 0 | I33: 0 | K33: 0 | M33: 0 | O33: 0 | AD33: 0 | AE33: 0 | AF33: 0 | AG33: 0 | AH33: 0 | AI33: 0 | AJ33: 0 | AK33: 0 | AL33: 0 | AM33: 0 | AN33: 0 | AO33: 0 | AQ33: 0 | AR33: 0 | AS33: 0 | AT33: 0 | AU33: 0 | AV33: 0 | AW33: 0 | AX33: 0 | AY33: 0 | AZ33: 0 | BA33: 0 | BB33: 0 | BD33: 0 | BE33: 0 | BF33: 0 | BG33: 0
C34: Comunidades ME | D34: 91243650 | E34: 83667.488 | F34: 85483.936 | G34: =F34*$F$51 -> 87841.21 | I34: 0 | K34: 0 | M34: 14047.465 | O34: 69620.023 | AD34: 0 | AE34: 0 | AF34: 0 | AG34: 0 | AH34: 0 | AI34: 0 | AJ34: 0 | AK34: 0 | AL34: 0 | AM34: 0 | AN34: 0 | AO34: 0 | AQ34: 0 | AR34: 0 | AS34: 0 | AT34: 0 | AU34: 0 | AV34: 0 | AW34: 0 | AX34: 0 | AY34: 0 | AZ34: 0 | BA34: 0 | BB34: 14047.465 | BD34: 0 | BE34: 0 | BF34: 69620.023 | BG34: 0
C35: Administración MN | D35: 91243660 | E35: 3820.5583 | F35: 783.34799 | G35: =F35*$E$51 -> 781.0761 | I35: 0 | K35: 0 | M35: 0 | O35: 3820.5583 | AD35: 0 | AE35: 0 | AF35: 0 | AG35: 0 | AH35: 0 | AI35: 0 | AJ35: 0 | AK35: 0 | AL35: 0 | AM35: 0 | AN35: 0 | AO35: 0 | AQ35: 0 | AR35: 0 | AS35: 0 | AT35: 0 | AU35: 0 | AV35: 0 | AW35: 0 | AX35: 0 | AY35: 0 | AZ35: 0 | BA35: 0 | BB35: 0 | BD35: 0 | BE35: 0 | BF35: 3820.5583 | BG35: 0
C36: Contingencia ME | D36: 91243750 | E36: 68117.701 | F36: 133558.82 | G36: =F36*$F$51 -> 137241.79 | I36: 0 | K36: 41310.498 | M36: 0 | O36: 26807.203 | AD36: 0 | AE36: 0 | AF36: 0 | AG36: 41310.498 | AH36: 0 | AI36: 0 | AJ36: 0 | AK36: 0 | AL36: 0 | AM36: 0 | AN36: 0 | AO36: 0 | AQ36: 0 | AR36: 0 | AS36: 0 | AT36: 0 | AU36: 0 | AV36: 0 | AW36: 0 | AX36: 0 | AY36: 0 | AZ36: 0 | BA36: 0 | BB36: 0 | BD36: 0 | BE36: 0 | BF36: 0 | BG36: 26807.203
C37: Fee MN | D37: 91243910 | E37: 101346.17 | F37: 103078.35 | G37: =F37*$E$51 -> 102779.4 | I37: 0 | K37: 27372.791 | M37: 34847.189 | O37: 39126.187 | AG37: 199.09502 | AH37: 7552.3314 | AI37: 3314.5339 | AJ37: 6305.224 | AK37: 1921.745 | AL37: 1921.745 | AM37: 1921.745 | AN37: 1921.745 | AO37: 2314.6273 | AQ37: 716.43245 | AR37: 716.43245 | AS37: 716.43245 | AT37: 8134.0149 | AU37: 8381.2676 | AV37: 8134.0149 | AW37: 716.43245 | AX37: 716.43245 | AY37: 716.43245 | AZ37: 716.43245 | BA37: 716.43245 | BB37: 4466.4325 | BD37: 37716.432 | BE37: 716.43245 | BF37: 693.32173 | BG37: 0
E40: 6571392.7 | I40: 655490.84 | K40: 1998016.6 | M40: 1999923.5 | O40: 1917961.8
C44: MN | E44: 1338082.6 | F44: =E44*E51 -> 1334201.9 | I44: 335729.46 | K44: 729942.61 | M44: 190876.04 | O44: 81534.524
C45: ME | E45: 5233310.1 | F45: =E45*F51 -> 5377622 | I45: 319761.38 | K45: 1268074 | M45: 1809047.5 | O45: 1836427.2
E46: 6571392.7 | I46: 655490.84 | K46: 1998016.6 | M46: 1999923.5 | O46: 1917961.8
...

Sheet Vor-RP
D2: ORIG | E2: RP
D3: TOTAL | E3: TOTAL
B4: Exploración Internacional Otros Países | D4: 6574033.2 | E4: =E5 -> 6744916.6
B5: E. Internacional Otros Países | D5: 6574033.2 | E5: =E6+E22 -> 6744916.6
B6: Metalotectos de Interés Item I | D6: 855289.16 | E6: =SUM(E7:E21) -> 355748.03
B7: Geología MN | C7: 91243110 | D7: 306215.66 | E7: ='Formato SAP'!E7 -> 257951.07
B8: Geología ME | C8: 91243120 | D8: 182663.51 | E8: ='Formato SAP'!E8 -> 73547.228
B9: Geoquímica ME | C9: 91243220 | D9: 0 | E9: ='Formato SAP'!E9 -> 0
B10: Geofísica ME | C10: 91243310 | D10: 0 | E10: ='Formato SAP'!E10 -> 0
B11: Sondajes ME | C11: 91243510 | D11: 0 | E11: ='Formato SAP'!E11 -> 0
B12: Logística MN | C12: 91243520 | D12: 142626.28 | E12: ='Formato SAP'!E12 -> 665.30466 | H12: 144957.87
B13: Logística ME | C13: 91243530 | D13: 138574.26 | E13: ='Formato SAP'!E13 -> -1909.942 | H13: 137937.38
B14: Propiedad Minera ME | C14: 91243610 | D14: 0 | E14: ='Formato SAP'!E14 -> 0
B15: Medio Ambiente MN | C15: 91243620 | D15: 0 | E15: ='Formato SAP'!E15 -> 0
B16: Medio Ambiente ME | C16: 91243630 | D16: 0 | E16: ='Formato SAP'!E16 -> 0
B17: Seguridad ME | C17: 91243640 | D17: 0 | E17: ='Formato SAP'!E17 -> 0
B18: Comunidades ME | C18: 91243650 | D18: 0 | E18: ='Formato SAP'!E18 -> 0
B19: Administración MN | C19: 91243660 | D19: 0 | E19: ='Formato SAP'!E19 -> 11960.166
B20: Contingencia ME | C20: 91243750 | D20: 58893.038 | E20: ='Formato SAP'!E20 -> 0
B21: Fee MN | C21: 91243910 | D21: 26316.421 | E21: ='Formato SAP'!E21 -> 13534.209
B22: Metalotectos de Interés Item II | D22: 5718744 | E22: ='Formato SAP'!E22 -> 6389168.5
B23: Geología MN | C23: 91243110 | D23: 481336.05 | E23: ='Formato SAP'!E23 -> 1172987.2
B24: Geología ME | C24: 91243120 | D24: 234099.91 | E24: ='Formato SAP'!E24 -> 1337011
B25: Geoquímica ME | C25: 91243220 | D25: 0 | E25: ='Formato SAP'!E25 -> 0
B26: Geofísica ME | C26: 91243310 | D26: 1657618.3 | E26: ='Formato SAP'!E26 -> 1703101.1
B27: Sondajes ME | C27: 91243510 | D27: 884063.1 | E27: ='Formato SAP'!E27 -> 908441.2
B28: Logística MN | C28: 91243520 | D28: 256590.47 | E28: ='Formato SAP'!E28 -> 314827.15 | H28: 242945.28 | I28: =H28+H12 -> 387903.15 | J28: =I28*I56 -> 0
B29: Logística ME | C29: 91243530 | D29: 170902.61 | E29: ='Formato SAP'!E29 -> 206407 | H29: 187956.98 | I29: =H29+H13 -> 325894.36 | J29: =I29*I57 -> 0
B30: Propiedad Minera ME | C30: 91243610 | D30: 1707849.2 | E30: ='Formato SAP'!E30 -> 340692
B31: Medio Ambiente MN | C31: 91243620 | D31: 0 | E31: ='Formato SAP'!E31 -> 0
B32: Medio Ambiente ME | C32: 91243630 | D32: 70323.201 | E32: ='Formato SAP'!E32 -> 72262.202
B33: Seguridad ME | C33: 91243640 | D33: 0 | E33: ='Formato SAP'!E33 -> 0
B34: Comunidades ME | C34: 91243650 | D34: 84053.794 | E34: ='Formato SAP'!E34 -> 87841.21
B35: Administración MN | C35: 91243660 | D35: 3759.106 | E35: ='Formato SAP'!E35 -> 8230.627
B36: Contingencia ME | C36: 91243750 | D36: 68432.211 | E36: ='Formato SAP'!E36 -> 137241.79
B37: Fee MN | C37: 91243910 | D37: 99716.05 | E37: ='Formato SAP'!E37 -> 100126.13
B42: TOTAL | D42: ORIG | E42: RP
D43: TOTAL | E43: TOTAL
B44: Exploración Internacional Otros Países | D44: =D45 -> 6574402.5 | E44: =E45 -> 6744916.6
B45: E. Internacional Otros Países | D45: =D46+D62 -> 6574402.5 | E45: =E46+E62 -> 6744916.6
...

Sheet Formato SAP
E2: 2024-2028 | G2: 2024 | I2: 2025 | K2: 2026 | M2: 2027 | O2: 2028 | Q2: PLANIFICACION AÑO 2024 | AD2: PLANIFICACION AÑO 2025 | AQ2: PLANIFICACION AÑO 2026 | BD2: PLANIFICACION AÑO 2027 | BQ2: PLANIFICACION AÑO 2028
E3: TOTAL | G3: TOTAL AÑO | I3: TOTAL AÑO | K3: TOTAL AÑO | M3: TOTAL AÑO | O3: TOTAL AÑO | Q3: 45322 | R3: 45351 | S3: 45382 | T3: 45412 | U3: 45443 | V3: 45473 | W3: 45504 | X3: 45535 | Y3: 45565 | Z3: 45596 | AA3: 45626 | AB3: 45657 | AD3: 45688 | AE3: 45716 | AF3: 45747 | AG3: 45777 | AH3: 45808 | AI3: 45838 | AJ3: 45869 | AK3: 45900 | AL3: 45930 | AM3: 45961 | AN3: 45991 | AO3: 46022 | AQ3: 46053 | AR3: 46081 | AS3: 46112 | AT3: 46142 | AU3: 46173 | AV3: 46203 | AW3: 46234 | AX3: 46265 | AY3: 46295 | AZ3: 46326 | BA3: 46356 | BB3: 46387 | BD3: 46053 | BE3: 46081 | BF3: 46112 | BG3: 46142 | BH3: 46173 | BI3: 46203 | BJ3: 46234 | BK3: 46265 | BL3: 46295 | BM3: 46326 | BN3: 46356 | BO3: 46387 | BQ3: 46053 | BR3: 46081 | BS3: 46112 | BT3: 46142 | BU3: 46173 | BV3: 46203 | BW3: 46234 | BX3: 46265 | BY3: 46295 | BZ3: 46326 | CA3: 46356 | CB3: 46387
C4: Exploración Internacional Otros Países | E4: =+E5 -> 6744916.6 | G4: =+G5 -> 228189.96 | I4: =+I5 -> 476667.45 | K4: =+K5 -> 1674600.4 | M4: =+M5 -> 2034249.7 | O4: =+O5 -> 2331209 | Q4: 0 | R4: 0 | S4: 0 | T4: 0 | U4: 0 | V4: 0 | W4: =+W5 -> 0 | X4: =+X5 -> 21748.877 | Y4: =+Y5 -> 24753.417 | Z4: =+Z5 -> 58248.926 | AA4: =+AA5 -> 71397.225 | AB4: =+AB5 -> 52041.513 | AD4: =+AD5 -> 43626.259 | AE4: =+AE5 -> 21064.505 | AF4: =+AF5 -> 57868.451 | AG4: =+AG5 -> 13727.544 | AH4: =+AH5 -> -8728.6852 | AI4: =+AI5 -> 3288.7309 | AJ4: =+AJ5 -> 18808.842 | AK4: =+AK5 -> 37716.249 | ... AO4: =+AO5 -> 129527.49 | AQ4: =+AQ5 -> 51205.759 | AR4: =+AR5 -> 141610.1 | AS4: =+AS5 -> 85751.189 | AT4: =+AT5 -> 167840.01 | AU4: =+AU5 -> 77005.517 | AV4: =+AV5 -> 243732.71 | AW4: =+AW5 -> 166508.08 | AX4: =+AX5 -> 62506.951 | ... BB4: =+BB5 -> 473054.62 | BD4: =+BD5 -> 445558.68 | BE4: =+BE5 -> 321275.77 | BF4: =+BF5 -> 481336.31 | BG4: =+BG5 -> 90864.362 | BH4: =+BH5 -> 81346.411 | BI4: =+BI5 -> 240676.62 | BJ4: =+BJ5 -> 77005.128 | BK4: =+BK5 -> 60528.503 | ... BO4: =+BO5 -> 59163.317 | BQ4: =+BQ5 -> 954863.42 | BR4: =+BR5 -> 452697.51 | BS4: =+BS5 -> 497211.73 | BT4: =+BT5 -> 426436.38 | BU4: =+BU5 -> 0 | BV4: =+BV5 -> 0 | BW4: =+BW5 -> 0 | BX4: =+BX5 -> 0 | ... CB4: =+CB5 -> 0
C5: E. Internacional Otros Países | E5: =+E6+E22 -> 6744916.6 | G5: =+G6+G22 -> 228189.96 | I5: =+I6+I22 -> 476667.45 | K5: =+K6+K22 -> 1674600.4 | M5: =+M6+M22 -> 2034249.7 | O5: =+O6+O22 -> 2331209 | Q5: 0 | R5: 0 | S5: 0 | T5: 0 | U5: 0 | V5: 0 | W5: =+W6 -> 0 | X5: =+X6 -> 21748.877 | Y5: =+Y6 -> 24753.417 | Z5: =+Z6 -> 58248.926 | AA5: =+AA6 -> 71397.225 | AB5: =+AB6 -> 52041.513 | AD5: =+AD6+AD22 -> 43626.259 | AE5: =+AE6+AE22 -> 21064.505 | AF5: =+AF6+AF22 -> 57868.451 | AG5: =+AG6+AG22 -> 13727.544 | AH5: =+AH6 -> -8728.6852 | AI5: =+AI6+AI22 -> 3288.7309 | AJ5: =+AJ6+AJ22 -> 18808.842 | AK5: =+AK6+AK22 -> 37716.249 | AL5: =+AL6+AL22 -> 39383.381 | AM5: =+AM6+AM22 -> 56904.187 | AN5: =+AN6+AN22 -> 63480.502 | AO5: =+AO6+AO22 -> 129527.49 | AP5: =+AP6+AP22 -> 0 | ... BO5: =+BO6+BO22 -> 59163.317 | BQ5: =+BQ6+BQ22 -> 954863.42 | BR5: =+BR6+BR22 -> 452697.51 | BS5: =+BS6+BS22 -> 497211.73 | BT5: =+BT6+BT22 -> 426436.38 | BU5: =+BU6+BU22 -> 0 | BV5: =+BV6+BV22 -> 0 | BW5: =+BW6+BW22 -> 0 | BX5: =+BX6+BX22 -> 0 | ... CB5: =+CB6+CB22 -> 0
C6: Metalotectos de Interés Item I | E6: =SUM(E7:E21) -> 355748.03 | G6: =SUM(G7:G21) -> 228189.96 | I6: =SUM(I7:I21) -> 127558.07 | K6: =SUM(K7:K21) -> 0 | M6: =SUM(M7:M21) -> 0 | O6: =SUM(O7:O21) -> 0 | Q6: 0 | R6: 0 | S6: 0 | T6: 0 | U6: 0 | V6: 0 | W6: =SUM(W7:W21) -> 0 | X6: =SUM(X7:X21) -> 21748.877 | Y6: =SUM(Y7:Y21) -> 24753.417 | Z6: =SUM(Z7:Z21) -> 58248.926 | AA6: =SUM(AA7:AA21) -> 71397.225 | AB6: =SUM(AB7:AB21) -> 52041.513 | AD6: =SUM(AD7:AD21) -> 43626.259 | AE6: =SUM(AE7:AE21) -> 21064.505 | AF6: =SUM(AF7:AF21) -> 57868.451 | AG6: =SUM(AG7:AG21) -> 13727.544 | AH6: =SUM(AH7:AH21) -> -8728.6852 | AI6: =SUM(AI7:AI21) -> 0 | AJ6: =SUM(AJ7:AJ21) -> 0 | AK6: =SUM(AK7:AK21) -> 0 | ... AO6: =SUM(AO7:AO21) -> 0 | AQ6: =SUM(AQ7:AQ21) -> 0 | AR6: =SUM(AR7:AR21) -> 0 | AS6: =SUM(AS7:AS21) -> 0 | AT6: =SUM(AT7:AT21) -> 0 | AU6: =SUM(AU7:AU21) -> 0 | AV6: =SUM(AV7:AV21) -> 0 | AW6: =SUM(AW7:AW21) -> 0 | AX6: =SUM(AX7:AX21) -> 0 | ... BB6: =SUM(BB7:BB21) -> 0 | BD6: =SUM(BD7:BD21) -> 0 | BE6: =SUM(BE7:BE21) -> 0 | BF6: =SUM(BF7:BF21) -> 0 | BG6: =SUM(BG7:BG21) -> 0 | BH6: =SUM(BH7:BH21) -> 0 | BI6: =SUM(BI7:BI21) -> 0 | BJ6: =SUM(BJ7:BJ21) -> 0 | BK6: =SUM(BK7:BK21) -> 0 | ... BO6: =SUM(BO7:BO21) -> 0 | BQ6: =SUM(BQ7:BQ21) -> 0 | BR6: =SUM(BR7:BR21) -> 0 | BS6: =SUM(BS7:BS21) -> 0 | BT6: =SUM(BT7:BT21) -> 0 | BU6: =SUM(BU7:BU21) -> 0 | BV6: =SUM(BV7:BV21) -> 0 | BW6: =SUM(BW7:BW21) -> 0 | BX6: =SUM(BX7:BX21) -> 0 | ... CB6: =SUM(CB7:CB21) -> 0
C7: Geología MN | D7: 91243110 | E7: =SUM(G7,I7,K7,M7) -> 257951.07 | G7: =SUM(Q7:AB7) -> 114348.9 | I7: =SUM(AD7:AO7) -> 143602.17 | K7: =SUM(AQ7:BB7) -> 0 | M7: =SUM(BD7:BO7) -> 0 | O7: =SUM(BF7:BQ7) -> 0 | X7: ='G2'!F5 -> 12378.409 | Y7: ='G2'!G5 -> 10182.36 | Z7: ='G2'!H5 -> 23485.148 | AA7: ='G2'!I5 -> 31742.915 | AB7: ='G2'!J5 -> 36560.068 | AD7: ='G2'!K5 -> 36762.03 | AE7: ='G2'!L5 -> 17427.218 | AF7: ='G2'!M5 -> 47239.649 | AG7: ='G2'!N5 -> 9877.9764 | AH7: ='G2'!O5 -> 32295.292
C8: Geología ME | D8: 91243120 | E8: =SUM(G8,I8,K8,M8) -> 73547.228 | G8: =SUM(Q8:AB8) -> 62050.552 | I8: =SUM(AD8:AO8) -> 11496.676 | K8: =SUM(AQ8:BB8) -> 0 | M8: =SUM(BD8:BO8) -> 0 | O8: =SUM(BF8:BQ8) -> 0 | X8: ='G2'!F6 -> 0 | Y8: ='G2'!G6 -> 7923.3141 | Z8: ='G2'!H6 -> 3931.0941 | AA8: ='G2'!I6 -> 39727.013 | AB8: ='G2'!J6 -> 10469.13 | AD8: ='G2'!K6 -> 4379.1953 | AE8: ='G2'!L6 -> 0 | AF8: ='G2'!M6 -> 1942.9534 | AG8: ='G2'!N6 -> 3398.8437 | AH8: ='G2'!O6 -> 1775.6841
C9: Geoquímica ME | D9: 91243220 | E9: =SUM(G9,I9,K9,M9) -> 0 | G9: =SUM(Q9:AB9) -> 0 | I9: =SUM(AD9:AO9) -> 0 | K9: =SUM(AQ9:BB9) -> 0 | M9: =SUM(BD9:BO9) -> 0 | O9: =SUM(BF9:BQ9) -> 0 | X9: ='G2'!F7 -> 0 | Y9: ='G2'!G7 -> 0 | Z9: ='G2'!H7 -> 0 | AA9: ='G2'!I7 -> 0 | AB9: ='G2'!J7 -> 0 | AD9: ='G2'!K7 -> 0 | AE9: ='G2'!L7 -> 0 | AF9: ='G2'!M7 -> 0 | AG9: ='G2'!N7 -> 0 | AH9: ='G2'!O7 -> 0
C10: Geofísica ME | D10: 91243310 | E10: =SUM(G10,I10,K10,M10) -> 0 | G10: =SUM(Q10:AB10) -> 0 | I10: =SUM(AD10:AO10) -> 0 | K10: =SUM(AQ10:BB10) -> 0 | M10: =SUM(BD10:BO10) -> 0 | O10: =SUM(BF10:BQ10) -> 0 | X10: ='G2'!F8 -> 0 | Y10: ='G2'!G8 -> 0 | Z10: ='G2'!H8 -> 0 | AA10: ='G2'!I8 -> 0 | AB10: ='G2'!J8 -> 0 | AD10: ='G2'!K8 -> 0 | AE10: ='G2'!L8 -> 0 | AF10: ='G2'!M8 -> 0 | AG10: ='G2'!N8 -> 0 | AH10: ='G2'!O8 -> 0
C11: Sondajes ME | D11: 91243510 | E11: =SUM(G11,I11,K11,M11) -> 0 | G11: =SUM(Q11:AB11) -> 0 | I11: =SUM(AD11:AO11) -> 0 | K11: =SUM(AQ11:BB11) -> 0 | M11: =SUM(BD11:BO11) -> 0 | O11: =SUM(BF11:BQ11) -> 0 | X11: ='G2'!F9 -> 0 | Y11: ='G2'!G9 -> 0 | Z11: ='G2'!H9 -> 0 | AA11: ='G2'!I9 -> 0 | AB11: ='G2'!J9 -> 0 | AD11: ='G2'!K9 -> 0 | AE11: ='G2'!L9 -> 0 | AF11: ='G2'!M9 -> 0 | AG11: ='G2'!N9 -> 0 | AH11: ='G2'!O9 -> 0
C12: Logística MN | D12: 91243520 | E12: =SUM(G12,I12,K12,M12) -> 665.30466 | G12: =SUM(Q12:AB12) -> 34560.192 | I12: =SUM(AD12:AO12) -> -33894.887 | K12: =SUM(AQ12:BB12) -> 0 | M12: =SUM(BD12:BO12) -> 0 | O12: =SUM(BF12:BQ12) -> 0 | X12: ='G2'!F10 -> 8892.6998 | Y12: ='G2'!G10 -> 5768.8417 | Z12: ='G2'!H10 -> 23445.938 | AA12: ='G2'!I10 -> 2833.7478 | AB12: ='G2'!J10 -> -6381.0353 | AD12: ='G2'!K10 -> 0 | AE12: ='G2'!L10 -> 0 | AF12: ='G2'!M10 -> 8069.1979 | AG12: ='G2'!N10 -> 0 | AH12: ='G2'!O10 -> -41964.085
C13: Logística ME | D13: 91243530 | E13: =SUM(G13,I13,K13,M13) -> -1909.942 | G13: =SUM(Q13:AB13) -> -125.16104 | I13: =SUM(AD13:AO13) -> -1784.7809 | K13: =SUM(AQ13:BB13) -> 0 | M13: =SUM(BD13:BO13) -> 0 | O13: =SUM(BF13:BQ13) -> 0 | X13: ='G2'!F11 -> 0 | Y13: ='G2'!G11 -> 0 | Z13: ='G2'!H11 -> 4713.5532 | AA13: ='G2'!I11 -> -4663.9872 | AB13: ='G2'!J11 -> -174.72702 | AD13: ='G2'!K11 -> 0 | AE13: ='G2'!L11 -> 0 | AF13: ='G2'!M11 -> 0 | AG13: ='G2'!N11 -> 0 | AH13: ='G2'!O11 -> -1784.7809
C14: Propiedad Minera ME | D14: 91243610 | E14: =SUM(G14,I14,K14,M14) -> 0 | G14: =SUM(Q14:AB14) -> 0 | I14: =SUM(AD14:AO14) -> 0 | K14: =SUM(AQ14:BB14) -> 0 | M14: =SUM(BD14:BO14) -> 0 | O14: =SUM(BF14:BQ14) -> 0 | X14: ='G2'!F12 -> 0 | Y14: ='G2'!G12 -> 0 | Z14: ='G2'!H12 -> 0 | AA14: ='G2'!I12 -> 0 | AB14: ='G2'!J12 -> 0 | AD14: ='G2'!K12 -> 0 | AE14: ='G2'!L12 -> 0 | AF14: ='G2'!M12 -> 0 | AG14: ='G2'!N12 -> 0 | AH14: ='G2'!O12 -> 0
C15: Medio Ambiente MN | D15: 91243620 | E15: =SUM(G15,I15,K15,M15) -> 0 | G15: =SUM(Q15:AB15) -> 0 | I15: =SUM(AD15:AO15) -> 0 | K15: =SUM(AQ15:BB15) -> 0 | M15: =SUM(BD15:BO15) -> 0 | O15: =SUM(BF15:BQ15) -> 0 | X15: ='G2'!F13 -> 0 | Y15: ='G2'!G13 -> 0 | Z15: ='G2'!H13 -> 0 | AA15: ='G2'!I13 -> 0 | AB15: ='G2'!J13 -> 0 | AD15: ='G2'!K13 -> 0 | AE15: ='G2'!L13 -> 0 | AF15: ='G2'!M13 -> 0 | AG15: ='G2'!N13 -> 0 | AH15: ='G2'!O13 -> 0
C16: Medio Ambiente ME | D16: 91243630 | E16: =SUM(G16,I16,K16,M16) -> 0 | G16: =SUM(Q16:AB16) -> 0 | I16: =SUM(AD16:AO16) -> 0 | K16: =SUM(AQ16:BB16) -> 0 | M16: =SUM(BD16:BO16) -> 0 | O16: =SUM(BF16:BQ16) -> 0 | X16: ='G2'!F14 -> 0 | Y16: ='G2'!G14 -> 0 | Z16: ='G2'!H14 -> 0 | AA16: ='G2'!I14 -> 0 | AB16: ='G2'!J14 -> 0 | AD16: ='G2'!K14 -> 0 | AE16: ='G2'!L14 -> 0 | AF16: ='G2'!M14 -> 0 | AG16: ='G2'!N14 -> 0 | AH16: ='G2'!O14 -> 0
C17: Seguridad ME | D17: 91243640 | E17: =SUM(G17,I17,K17,M17) -> 0 | G17: =SUM(Q17:AB17) -> 0 | I17: =SUM(AD17:AO17) -> 0 | K17: =SUM(AQ17:BB17) -> 0 | M17: =SUM(BD17:BO17) -> 0 | O17: =SUM(BF17:BQ17) -> 0 | X17: ='G2'!F15 -> 0 | Y17: ='G2'!G15 -> 0 | Z17: ='G2'!H15 -> 0 | AA17: ='G2'!I15 -> 0 | AB17: ='G2'!J15 -> 0 | AD17: ='G2'!K15 -> 0 | AE17: ='G2'!L15 -> 0 | AF17: ='G2'!M15 -> 0 | AG17: ='G2'!N15 -> 0 | AH17: ='G2'!O15 -> 0
C18: Comunidades ME | D18: 91243650 | E18: =SUM(G18,I18,K18,M18) -> 0 | G18: =SUM(Q18:AB18) -> 0 | I18: =SUM(AD18:AO18) -> 0 | K18: =SUM(AQ18:BB18) -> 0 | M18: =SUM(BD18:BO18) -> 0 | O18: =SUM(BF18:BQ18) -> 0 | X18: ='G2'!F16 -> 0 | Y18: ='G2'!G16 -> 0 | Z18: ='G2'!H16 -> 0 | AA18: ='G2'!I16 -> 0 | AB18: ='G2'!J16 -> 0 | AD18: ='G2'!K16 -> 0 | AE18: ='G2'!L16 -> 0 | AF18: ='G2'!M16 -> 0 | AG18: ='G2'!N16 -> 0 | AH18: ='G2'!O16 -> 0
... C20: Contingencia ME | D20: 91243750 | E20: =SUM(G20,I20,K20,M20) -> 0 | G20: =SUM(Q20:AB20) -> 0 | I20: =SUM(AD20:AO20) -> 0 | K20: =SUM(AQ20:BB20) -> 0 | M20: =SUM(BD20:BO20) -> 0 | O20: =SUM(BF20:BQ20) -> 0 | X20: ='G2'!F18 -> 0 | Y20: ='G2'!G18 -> 0 | Z20: ='G2'!H18 -> 0 | AA20: ='G2'!I18 -> 0 | AB20: ='G2'!J18 -> 0 | AD20: ='G2'!K18 -> 0 | AE20: ='G2'!L18 -> 0 | AF20: ='G2'!M18 -> 0 | AG20: ='G2'!N18 -> 0 | AH20: ='G2'!O18 -> 0
C21: Fee MN | D21: 91243910 | E21: =SUM(G21,I21,K21,M21) -> 13534.209 | G21: =SUM(Q21:AB21) -> 8398.8917 | I21: =SUM(AD21:AO21) -> 5135.3171 | K21: =SUM(AQ21:BB21) -> 0 | M21: =SUM(BD21:BO21) -> 0 | O21: =SUM(BF21:BQ21) -> 0 | X21: ='G2'!F20+'G2'!F21 -> 477.76831 | Y21: ='G2'!G20+'G2'!G21 -> 878.90031 | Z21: ='G2'!H20+'G2'!H21 -> 2673.1929 | AA21: ='G2'!I20+'G2'!I21 -> 1757.5362 | AB21: ='G2'!J20+'G2'!J21 -> 2611.4939 | AD21: ='G2'!K20+'G2'!K21 -> 2485.0338 | AE21: ='G2'!L20+'G2'!L21 -> 710.64931 | AF21: ='G2'!M20+'G2'!M21 -> 539.70597 | AG21: ='G2'!N20+'G2'!N21 -> 450.72355 | AH21: ='G2'!O20+'G2'!O21 -> 949.2045
C22: Metalotectos de Interés Item II | E22: =SUM(E23:E37) -> 6389168.5 | G22: =SUM(G23:G37) -> 0 | I22: =SUM(I23:I37) -> 349109.38 | K22: =SUM(K23:K37) -> 1674600.4 | M22: =SUM(M23:M37) -> 2034249.7 | O22: =SUM(O23:O37) -> 2331209 | Q22: 0 | R22: 0 | S22: 0 | T22: 0 | U22: 0 | V22: 0 | W22: =SUM(W23:W37) -> 0 | X22: =SUM(X23:X37) -> 0 | Y22: =SUM(Y23:Y37) -> 0 | Z22: =SUM(Z23:Z37) -> 0 | AA22: =SUM(AA23:AA37) -> 0 | AB22: =SUM(AB23:AB37) -> 0 | AD22: =SUM(AD23:AD37) -> 0 | AE22: =SUM(AE23:AE37) -> 0 | AF22: =SUM(AF23:AF37) -> 0 | AG22: =SUM(AG23:AG37) -> 0 | AH22: =SUM(AH23:AH37) -> 0 | AI22: =SUM(AI23:AI37) -> 3288.7309 | AJ22: =SUM(AJ23:AJ37) -> 18808.842 | AK22: =SUM(AK23:AK37) -> 37716.249 | ... AO22: =SUM(AO23:AO37) -> 129527.49 | AQ22: =SUM(AQ23:AQ37) -> 51205.759 | AR22: =SUM(AR23:AR37) -> 141610.1 | AS22: =SUM(AS23:AS37) -> 85751.189 | AT22: =SUM(AT23:AT37) -> 167840.01 | AU22: =SUM(AU23:AU37) -> 77005.517 | AV22: =SUM(AV23:AV37) -> 243732.71 | AW22: =SUM(AW23:AW37) -> 166508.08 | AX22: =SUM(AX23:AX37) -> 62506.951 | ... BB22: =SUM(BB23:BB37) -> 473054.62 | BD22: =SUM(BD23:BD37) -> 445558.68 | BE22: =SUM(BE23:BE37) -> 321275.77 | BF22: =SUM(BF23:BF37) -> 481336.31 | BG22: =SUM(BG23:BG37) -> 90864.362 | BH22: =SUM(BH23:BH37) -> 81346.411 | BI22: =SUM(BI23:BI37) -> 240676.62 | BJ22: =SUM(BJ23:BJ37) -> 77005.128 | BK22: =SUM(BK23:BK37) -> 60528.503 | ... BO22: =SUM(BO23:BO37) -> 59163.317 | BQ22: =SUM(BQ23:BQ37) -> 954863.42 | BR22: =SUM(BR23:BR37) -> 452697.51 | BS22: =SUM(BS23:BS37) -> 497211.73 | BT22: =SUM(BT23:BT37) -> 426436.38 | BU22: =SUM(BU23:BU37) -> 0 | BV22: =SUM(BV23:BV37) -> 0 | BW22: =SUM(BW23:BW37) -> 0 | BX22: =SUM(BX23:BX37) -> 0 | ... CB22: =SUM(CB23:CB37) -> 0
C23: Geología MN | D23: 91243110 | E23: =SUM(G23,I23,K23,M23,O23) -> 1172987.2 | G23: =SUM(Q23:AB23) -> 0 | I23: =SUM(AD23:AO23) -> 166801.34 | K23: =SUM(AQ23:BB23) -> 405733.35 | M23: =SUM(BD23:BO23) -> 429592.71 | O23: =SUM(BQ23:CB23) -> 170859.77 | AI23: ='G2'!P5 -> 3138.7192 | AJ23: ='G2'!Q5 -> 17880.952 | AK23: ='G2'!R5 -> 27566.242 | AL23: ='G2'!S5 -> 28961.285 | AM23: ='G2'!T5 -> 27516.976 | AN23: ='G2'!U5 -> 27686.975 | AO23: ='G2'!V5 -> 34050.191 | AQ23: ='G2'!W5 -> 22330.695 | AR23: ='G2'!X5 -> 32333.243 | AS23: ='G2'!Y5 -> 38517.066 | AT23: ='G2'!Z5 -> 45624.881 | AU23: ='G2'!AA5 -> 38517.066 | AV23: ='G2'!AB5 -> 41820.587 | AW23: ='G2'!AC5 -> 38517.066 | AX23: ='G2'!AD5 -> 29781.565 | ... BB23: ='G2'!AH5 -> 29781.565 | BD23: ='G2'!AI5 -> 31072.688 | BE23: ='G2'!AJ5 -> 29657.695 | BF23: ='G2'!AK5 -> 48187.583 | BG23: ='G2'!AL5 -> 39999.23 | BH23: ='G2'!AM5 -> 40578.993 | BI23: ='G2'!AN5 -> 43803.524 | BJ23: ='G2'!AO5 -> 40578.993 | BK23: ='G2'!AP5 -> 32366.581 | ... BO23: ='G2'!AT5 -> 31072.688 | BQ23: ='G2'!AU5 -> 89315.397 | BR23: ='G2'!AV5 -> 30129.359 | BS23: ='G2'!AW5 -> 31072.688 | BT23: ='G2'!AX5 -> 20342.325 | BU23: ='G2'!AY5 -> 0 | BV23: ='G2'!AZ5 -> 0 | BW23: ='G2'!BA5 -> 0 | BX23: ='G2'!BB5 -> 0 | ... CB23: ='G2'!BF5 -> 0
C24: Geología ME | D24: 91243120 | E24: =SUM(G24,I24,K24,M24,O24) -> 1337011 | G24: =SUM(Q24:AB24) -> 0 | I24: =SUM(AD24:AO24) -> 55339.997 | K24: =SUM(AQ24:BB24) -> 418417.1 | M24: =SUM(BD24:BO24) -> 434267.95 | O24: =SUM(BQ24:CB24) -> 428985.95 | AI24: ='G2'!P6 -> 0 | AJ24: ='G2'!Q6 -> 0 | AK24: ='G2'!R6 -> 0 | AL24: ='G2'!S6 -> 8202.506 | AM24: ='G2'!T6 -> 13865.574 | AN24: ='G2'!U6 -> 0.0010971051 | AO24: ='G2'!V6 -> 33271.915 | AQ24: ='G2'!W6 -> 10773.278 | AR24: ='G2'!X6 -> 52560.391 | AS24: ='G2'!Y6 -> 28233.43 | AT24: ='G2'!Z6 -> 71272.505 | AU24: ='G2'!AA6 -> 29145.125 | AV24: ='G2'!AB6 -> 50597.12 | AW24: ='G2'!AC6 -> 29145.125 | AX24: ='G2'!AD6 -> 29145.125 | ... BB24: ='G2'!AH6 -> 28638.353 | BD24: ='G2'!AI6 -> 28638.353 | BE24: ='G2'!AJ6 -> 33457.012 | BF24: ='G2'!AK6 -> 82259.998 | BG24: ='G2'!AL6 -> 38716.417 | BH24: ='G2'!AM6 -> 33513.019 | BI24: ='G2'!AN6 -> 54824.114 | BJ24: ='G2'!AO6 -> 33513.019 | BK24: ='G2'!AP6 -> 25869.204 | ... BO24: ='G2'!AT6 -> 25869.204 | BQ24: ='G2'!AU6 -> 321031.64 | BR24: ='G2'!AV6 -> 35647.584 | BS24: ='G2'!AW6 -> 36321.955 | BT24: ='G2'!AX6 -> 35984.769 | BU24: ='G2'!AY6 -> 0 | BV24: ='G2'!AZ6 -> 0 | BW24: ='G2'!BA6 -> 0 | BX24: ='G2'!BB6 -> 0 | ... CB24: ='G2'!BF6 -> 0
C25: Geoquímica ME | D25: 91243220 | E25: =SUM(G25,I25,K25,M25,O25) -> 0 | G25: =SUM(Q25:AB25) -> 0 | I25: =SUM(AD25:AO25) -> 0 | K25: =SUM(AQ25:BB25) -> 0 | M25: =SUM(BD25:BO25) -> 0 | O25: =SUM(BQ25:CB25) -> 0 | AI25: ='G2'!P7 -> 0 | AJ25: ='G2'!Q7 -> 0 | AK25: ='G2'!R7 -> 0 | AL25: ='G2'!S7 -> 0 | AM25: ='G2'!T7 -> 0 | AN25: ='G2'!U7 -> 0 | AO25: ='G2'!V7 -> 0 | AQ25: ='G2'!W7 -> 0 | AR25: ='G2'!X7 -> 0 | AS25: ='G2'!Y7 -> 0 | AT25: ='G2'!Z7 -> 0 | AU25: ='G2'!AA7 -> 0 | AV25: ='G2'!AB7 -> 0 | AW25: ='G2'!AC7 -> 0 | AX25: ='G2'!AD7 -> 0 | ... BB25: ='G2'!AH7 -> 0 | BD25: ='G2'!AI7 -> 0 | BE25: ='G2'!AJ7 -> 0 | BF25: ='G2'!AK7 -> 0 | BG25: ='G2'!AL7 -> 0 | BH25: ='G2'!AM7 -> 0 | BI25: ='G2'!AN7 -> 0 | BJ25: ='G2'!AO7 -> 0 | BK25: ='G2'!AP7 -> 0 | ... BO25: ='G2'!AT7 -> 0 | BQ25: ='G2'!AU7 -> 0 | BR25: ='G2'!AV7 -> 0 | BS25: ='G2'!AW7 -> 0 | BT25: ='G2'!AX7 -> 0 | BU25: ='G2'!AY7 -> 0 | BV25: ='G2'!AZ7 -> 0 | BW25: ='G2'!BA7 -> 0 | BX25: ='G2'!BB7 -> 0 | ... CB25: ='G2'!BF7 -> 0
C26: Geofísica ME | D26: 91243310 | E26: =SUM(G26,I26,K26,M26,O26) -> 1703101.1 | G26: =SUM(Q26:AB26) -> 0 | I26: =SUM(AD26:AO26) -> 0 | K26: =SUM(AQ26:BB26) -> 342561.73 | M26: =SUM(BD26:BO26) -> 831440.7 | O26: =SUM(BQ26:CB26) -> 529098.63 | AI26: ='G2'!P8 -> 0 | AJ26: ='G2'!Q8 -> 0 | AK26: ='G2'!R8 -> 0 | AL26: ='G2'!S8 -> 0 | AM26: ='G2'!T8 -> 0 | AN26: ='G2'!U8 -> 0 | AO26: ='G2'!V8 -> 0 | AQ26: ='G2'!W8 -> 0 | AR26: ='G2'!X8 -> 0 | AS26: ='G2'!Y8 -> 0 | AT26: ='G2'!Z8 -> 0 | AU26: ='G2'!AA8 -> 0 | AV26: ='G2'!AB8 -> 0 | AW26: ='G2'!AC8 -> 0 | AX26: ='G2'!AD8 -> 0 | ... BB26: ='G2'!AH8 -> 342561.73 | BD26: ='G2'!AI8 -> 283238.04 | BE26: ='G2'!AJ8 -> 255827.91 | BF26: ='G2'!AK8 -> 283238.04 | BG26: ='G2'!AL8 -> 9136.711 | BH26: ='G2'!AM8 -> 0 | BI26: ='G2'!AN8 -> 0 | BJ26: ='G2'!AO8 -> 0 | BK26: ='G2'!AP8 -> 0 | ... BO26: ='G2'!AT8 -> 0 | BQ26: ='G2'!AU8 -> 178283.23 | BR26: ='G2'!AV8 -> 166781.09 | BS26: ='G2'!AW8 -> 178283.23 | BT26: ='G2'!AX8 -> 5751.072 | BU26: ='G2'!AY8 -> 0 | BV26: ='G2'!AZ8 -> 0 | BW26: ='G2'!BA8 -> 0 | BX26: ='G2'!BB8 -> 0 | ... CB26: ='G2'!BF8 -> 0
C27: Sondajes ME | D27: 91243510 | E27: =SUM(G27,I27,K27,M27,O27) -> 908441.2 | G27: =SUM(Q27:AB27) -> 0 | I27: =SUM(AD27:AO27) -> 0 | K27: =SUM(AQ27:BB27) -> 0 | M27: =SUM(BD27:BO27) -> 0 | O27: =SUM(BQ27:CB27) -> 908441.2 | AI27: ='G2'!P9 -> 0 | AJ27: ='G2'!Q9 -> 0 | AK27: ='G2'!R9 -> 0 | AL27: ='G2'!S9 -> 0 | AM27: ='G2'!T9 -> 0 | AN27: ='G2'!U9 -> 0 | AO27: ='G2'!V9 -> 0 | AQ27: ='G2'!W9 -> 0 | AR27: ='G2'!X9 -> 0 | AS27: ='G2'!Y9 -> 0 | AT27: ='G2'!Z9 -> 0 | AU27: ='G2'!AA9 -> 0 | AV27: ='G2'!AB9 -> 0 | AW27: ='G2'!AC9 -> 0 | AX27: ='G2'!AD9 -> 0 | ... BB27: ='G2'!AH9 -> 0 | BD27: ='G2'!AI9 -> 0 | BE27: ='G2'!AJ9 -> 0 | BF27: ='G2'!AK9 -> 0 | BG27: ='G2'!AL9 -> 0 | BH27: ='G2'!AM9 -> 0 | BI27: ='G2'!AN9 -> 0 | BJ27: ='G2'!AO9 -> 0 | BK27: ='G2'!AP9 -> 0 | ... BO27: ='G2'!AT9 -> 0 | BQ27: ='G2'!AU9 -> 232741.13 | BR27: ='G2'!AV9 -> 217725.58 | BS27: ='G2'!AW9 -> 232741.13 | BT27: ='G2'!AX9 -> 225233.35 | BU27: ='G2'!AY9 -> 0 | BV27: ='G2'!AZ9 -> 0 | BW27: ='G2'!BA9 -> 0 | BX27: ='G2'!BB9 -> 0 | ... CB27: ='G2'!BF9 -> 0
C28: Logística MN | D28: 91243520 | E28: =SUM(G28,I28,K28,M28,O28) -> 314827.15 | G28: =SUM(Q28:AB28) -> 0 | I28: =SUM(AD28:AO28) -> 109488.13 | K28: =SUM(AQ28:BB28) -> 77912.711 | M28: =SUM(BD28:BO28) -> 87445.543 | O28: =SUM(BQ28:CB28) -> 39980.767 | AI28: ='G2'!P10 -> 0 | AJ28: ='G2'!Q10 -> 0 | AK28: ='G2'!R10 -> 8620.6651 | AL28: ='G2'!S10 -> 1012.9016 | AM28: ='G2'!T10 -> 13594.026 | AN28: ='G2'!U10 -> 34373.876 | AO28: ='G2'!V10 -> 51886.662 | AQ28: ='G2'!W10 -> 16885.307 | AR28: ='G2'!X10 -> 19126.215 | AS28: ='G2'!Y10 -> 0 | AT28: ='G2'!Z10 -> 23443.536 | AU28: ='G2'!AA10 -> 0 | AV28: ='G2'!AB10 -> 18457.654 | AW28: ='G2'!AC10 -> 0 | AX28: ='G2'!AD10 -> 0 | ... BB28: ='G2'!AH10 -> 0 | BD28: ='G2'!AI10 -> 41732.893 | BE28: ='G2'!AJ10 -> 0 | BF28: ='G2'!AK10 -> 23297.897 | BG28: ='G2'!AL10 -> 0 | BH28: ='G2'!AM10 -> 0 | BI28: ='G2'!AN10 -> 22414.753 | BJ28: ='G2'!AO10 -> 0 | BK28: ='G2'!AP10 -> 0 | ... BO28: ='G2'!AT10 -> 0 | BQ28: ='G2'!AU10 -> 39980.767 | BR28: ='G2'!AV10 -> 0 | BS28: ='G2'!AW10 -> 0 | BT28: ='G2'!AX10 -> 0 | BU28: ='G2'!AY10 -> 0 | BV28: ='G2'!AZ10 -> 0 | BW28: ='G2'!BA10 -> 0 | BX28: ='G2'!BB10 -> 0 | ... CB28: ='G2'!BF10 -> 0
C29: Logística ME | D29: 91243530 | E29: =SUM(G29,I29,K29,M29,O29) -> 206407 | G29: =SUM(Q29:AB29) -> 0 | I29: =SUM(AD29:AO29) -> 1.0231815e-12 | K29: =SUM(AQ29:BB29) -> 100676.49 | M29: =SUM(BD29:BO29) -> 89818.332 | O29: =SUM(BQ29:CB29) -> 15912.175 | AI29: ='G2'!P11 -> 0 | AJ29: ='G2'!Q11 -> 0 | AK29: ='G2'!R11 -> 0 | AL29: ='G2'!S11 -> 0 | AM29: ='G2'!T11 -> 0 | AN29: ='G2'!U11 -> 0 | AO29: ='G2'!V11 -> 1.0231815e-12 | AQ29: ='G2'!W11 -> 0 | AR29: ='G2'!X11 -> 33432.627 | AS29: ='G2'!Y11 -> 15912.175 | AT29: ='G2'!Z11 -> 22423.109 | AU29: ='G2'!AA11 -> 0 | AV29: ='G2'!AB11 -> 28908.583 | AW29: ='G2'!AC11 -> 0 | AX29: ='G2'!AD11 -> 0 | ... BB29: ='G2'!AH11 -> 0 | BD29: ='G2'!AI11 -> 0 | BE29: ='G2'!AJ11 -> 0 | BF29: ='G2'!AK11 -> 38486.187 | BG29: ='G2'!AL11 -> 0 | BH29: ='G2'!AM11 -> 0 | BI29: ='G2'!AN11 -> 51332.145 | BJ29: ='G2'!AO11 -> 0 | BK29: ='G2'!AP11 -> 0 | ... BO29: ='G2'!AT11 -> 0 | BQ29: ='G2'!AU11 -> 0 | BR29: ='G2'!AV11 -> 0 | BS29: ='G2'!AW11 -> 15912.175 | BT29: ='G2'!AX11 -> 0 | BU29: ='G2'!AY11 -> 0 | BV29: ='G2'!AZ11 -> 0 | BW29: ='G2'!BA11 -> 0 | BX29: ='G2'!BB11 -> 0 | ... CB29: ='G2'!BF11 -> 0
C30: Propiedad Minera ME | D30: 91243610 | E30: =SUM(G30,I30,K30,M30,O30) -> 340692 | G30: =SUM(Q30:AB30) -> 0 | I30: =SUM(AD30:AO30) -> 0 | K30: =SUM(AQ30:BB30) -> 222430.69 | M30: =SUM(BD30:BO30) -> 36991.406 | O30: =SUM(BQ30:CB30) -> 81269.903 | AI30: ='G2'!P12 -> 0 | AJ30: ='G2'!Q12 -> 0 | AK30: ='G2'!R12 -> 0 | AL30: ='G2'!S12 -> 0 | AM30: ='G2'!T12 -> 0 | AN30: ='G2'!U12 -> 0 | AO30: ='G2'!V12 -> 0 | AQ30: ='G2'!W12 -> 0 | AR30: ='G2'!X12 -> 0 | AS30: ='G2'!Y12 -> 0 | AT30: ='G2'!Z12 -> 0 | AU30: ='G2'!AA12 -> 6629.8193 | AV30: ='G2'!AB12 -> 99447.29 | AW30: ='G2'!AC12 -> 96132.38 | AX30: ='G2'!AD12 -> 1348.0801 | ... BB30: ='G2'!AH12 -> 0 | BD30: ='G2'!AI12 -> 36991.406 | BE30: ='G2'!AJ12 -> 0 | BF30: ='G2'!AK12 -> 0 | BG30: ='G2'!AL12 -> 0 | BH30: ='G2'!AM12 -> 0 | BI30: ='G2'!AN12 -> 0 | BJ30: ='G2'!AO12 -> 0 | BK30: ='G2'!AP12 -> 0 | ... BO30: ='G2'!AT12 -> 0 | BQ30: ='G2'!AU12 -> 81269.903 | BR30: ='G2'!AV12 -> 0 | BS30: ='G2'!AW12 -> 0 | BT30: ='G2'!AX12 -> 0 | BU30: ='G2'!AY12 -> 0 | BV30: ='G2'!AZ12 -> 0 | BW30: ='G2'!BA12 -> 0 | BX30: ='G2'!BB12 -> 0 | ... CB30: ='G2'!BF12 -> 0
C31: Medio Ambiente MN | D31: 91243620 | E31: =SUM(G31,I31,K31,M31,O31) -> 0 | G31: =SUM(Q31:AB31) -> 0 | I31: =SUM(AD31:AO31) -> 0 | K31: =SUM(AQ31:BB31) -> 0 | M31: =SUM(BD31:BO31) -> 0 | O31: =SUM(BQ31:CB31) -> 0 | AI31: ='G2'!P13 -> 0 | AJ31: ='G2'!Q13 -> 0 | AK31: ='G2'!R13 -> 0 | AL31: ='G2'!S13 -> 0 | AM31: ='G2'!T13 -> 0 | AN31: ='G2'!U13 -> 0 | AO31: ='G2'!V13 -> 0 | AQ31: ='G2'!W13 -> 0 | AR31: ='G2'!X13 -> 0 | AS31: ='G2'!Y13 -> 0 | AT31: ='G2'!Z13 -> 0 | AU31: ='G2'!AA13 -> 0 | AV31: ='G2'!AB13 -> 0 | AW31: ='G2'!AC13 -> 0 | AX31: ='G2'!AD13 -> 0 | ... BB31: ='G2'!AH13 -> 0 | BD31: ='G2'!AI13 -> 0 | BE31: ='G2'!AJ13 -> 0 | BF31: ='G2'!AK13 -> 0 | BG31: ='G2'!AL13 -> 0 | BH31: ='G2'!AM13 -> 0 | BI31: ='G2'!AN13 -> 0 | BJ31: ='G2'!AO13 -> 0 | BK31: ='G2'!AP13 -> 0 | ... BO31: ='G2'!AT13 -> 0 | BQ31: ='G2'!AU13 -> 0 | BR31: ='G2'!AV13 -> 0 | BS31: ='G2'!AW13 -> 0 | BT31: ='G2'!AX13 -> 0 | BU31: ='G2'!AY13 -> 0 | BV31: ='G2'!AZ13 -> 0 | BW31: ='G2'!BA13 -> 0 | BX31: ='G2'!BB13 -> 0 | ... CB31: ='G2'!BF13 -> 0
C32: Medio Ambiente ME | D32: 91243630 | E32: =SUM(G32,I32,K32,M32,O32) -> 72262.202 | G32: =SUM(Q32:AB32) -> 0 | I32: =SUM(AD32:AO32) -> 0 | K32: =SUM(AQ32:BB32) -> 72262.202 | M32: =SUM(BD32:BO32) -> 0 | O32: =SUM(BQ32:CB32) -> 0 | AI32: ='G2'!P14 -> 0 | AJ32: ='G2'!Q14 -> 0 | AK32: ='G2'!R14 -> 0 | AL32: ='G2'!S14 -> 0 | AM32: ='G2'!T14 -> 0 | AN32: ='G2'!U14 -> 0 | AO32: ='G2'!V14 -> 0 | AQ32: ='G2'!W14 -> 0 | AR32: ='G2'!X14 -> 0 | AS32: ='G2'!Y14 -> 0 | AT32: ='G2'!Z14 -> 0 | AU32: ='G2'!AA14 -> 0 | AV32: ='G2'!AB14 -> 0 | AW32: ='G2'!AC14 -> 0 | AX32: ='G2'!AD14 -> 0 | ... BB32: ='G2'!AH14 -> 69853.462 | BD32: ='G2'!AI14 -> 0 | BE32: ='G2'!AJ14 -> 0 | BF32: ='G2'!AK14 -> 0 | BG32: ='G2'!AL14 -> 0 | BH32: ='G2'!AM14 -> 0 | BI32: ='G2'!AN14 -> 0 | BJ32: ='G2'!AO14 -> 0 | BK32: ='G2'!AP14 -> 0 | ... BO32: ='G2'!AT14 -> 0 | BQ32: ='G2'!AU14 -> 0 | BR32: ='G2'!AV14 -> 0 | BS32: ='G2'!AW14 -> 0 | BT32: ='G2'!AX14 -> 0 | BU32: ='G2'!AY14 -> 0 | BV32: ='G2'!AZ14 -> 0 | BW32: ='G2'!BA14 -> 0 | BX32: ='G2'!BB14 -> 0 | ... CB32: ='G2'!BF14 -> 0
C33: Seguridad ME | D33: 91243640 | E33: =SUM(G33,I33,K33,M33,O33) -> 0 | G33: =SUM(Q33:AB33) -> 0 | I33: =SUM(AD33:AO33) -> 0 | K33: =SUM(AQ33:BB33) -> 0 | M33: =SUM(BD33:BO33) -> 0 | O33: =SUM(BQ33:CB33) -> 0 | AI33: ='G2'!P15 -> 0 | AJ33: ='G2'!Q15 -> 0 | AK33: ='G2'!R15 -> 0 | AL33: ='G2'!S15 -> 0 | AM33: ='G2'!T15 -> 0 | AN33: ='G2'!U15 -> 0 | AO33: ='G2'!V15 -> 0 | AQ33: ='G2'!W15 -> 0 | AR33: ='G2'!X15 -> 0 | AS33: ='G2'!Y15 -> 0 | AT33: ='G2'!Z15 -> 0 | AU33: ='G2'!AA15 -> 0 | AV33: ='G2'!AB15 -> 0 | AW33: ='G2'!AC15 -> 0 | AX33: ='G2'!AD15 -> 0 | ... BB33: ='G2'!AH15 -> 0 | BD33: ='G2'!AI15 -> 0 | BE33: ='G2'!AJ15 -> 0 | BF33: ='G2'!AK15 -> 0 | BG33: ='G2'!AL15 -> 0 | BH33: ='G2'!AM15 -> 0 | BI33: ='G2'!AN15 -> 0 | BJ33: ='G2'!AO15 -> 0 | BK33: ='G2'!AP15 -> 0 | ... BO33: ='G2'!AT15 -> 0 | BQ33: ='G2'!AU15 -> 0 | BR33: ='G2'!AV15 -> 0 | BS33: ='G2'!AW15 -> 0 | BT33: ='G2'!AX15 -> 0 | BU33: ='G2'!AY15 -> 0 | BV33: ='G2'!AZ15 -> 0 | BW33: ='G2'!BA15 -> 0 | BX33: ='G2'!BB15 -> 0 | ... CB33: ='G2'!BF15 -> 0
C34: Comunidades ME | D34: 91243650 | E34: =SUM(G34,I34,K34,M34,O34) -> 87841.21 | G34: =SUM(Q34:AB34) -> 0 | I34: =SUM(AD34:AO34) -> 0 | K34: =SUM(AQ34:BB34) -> 0 | M34: =SUM(BD34:BO34) -> 87841.21 | O34: =SUM(BQ34:CB34) -> 0 | AI34: ='G2'!P16 -> 0 | AJ34: ='G2'!Q16 -> 0 | AK34: ='G2'!R16 -> 0 | AL34: ='G2'!S16 -> 0 | AM34: ='G2'!T16 -> 0 | AN34: ='G2'!U16 -> 0 | AO34: ='G2'!V16 -> 0 | AQ34: ='G2'!W16 -> 0 | AR34: ='G2'!X16 -> 0 | AS34: ='G2'!Y16 -> 0 | AT34: ='G2'!Z16 -> 0 | AU34: ='G2'!AA16 -> 0 | AV34: ='G2'!AB16 -> 0 | AW34: ='G2'!AC16 -> 0 | AX34: ='G2'!AD16 -> 0 | ... BB34: ='G2'!AH16 -> 0 | BD34: ='G2'!AI16 -> 20551.325 | BE34: ='G2'!AJ16 -> 0 | BF34: ='G2'!AK16 -> 0 | BG34: ='G2'!AL16 -> 0 | BH34: ='G2'!AM16 -> 4341.2829 | BI34: ='G2'!AN16 -> 62948.602 | BJ34: ='G2'!AO16 -> 0 | BK34: ='G2'!AP16 -> 0 | ... BO34: ='G2'!AT16 -> 0 | BQ34: ='G2'!AU16 -> 0 | BR34: ='G2'!AV16 -> 0 | BS34: ='G2'!AW16 -> 0 | BT34: ='G2'!AX16 -> 0 | BU34: ='G2'!AY16 -> 0 | BV34: ='G2'!AZ16 -> 0 | BW34: ='G2'!BA16 -> 0 | BX34: ='G2'!BB16 -> 0 | ... CB34: ='G2'!BF16 -> 0
... C36: Contingencia ME | D36: 91243750 | E36: =SUM(G36,I36,K36,M36,O36) -> 137241.79 | G36: =SUM(Q36:AB36) -> 0 | I36: =SUM(AD36:AO36) -> 0 | K36: =SUM(AQ36:BB36) -> 0 | M36: =SUM(BD36:BO36) -> 0 | O36: =SUM(BQ36:CB36) -> 137241.79 | AI36: ='G2'!P18 -> 0 | AJ36: ='G2'!Q18 -> 0 | AK36: ='G2'!R18 -> 0 | AL36: ='G2'!S18 -> 0 | AM36: ='G2'!T18 -> 0 | AN36: ='G2'!U18 -> 0 | AO36: ='G2'!V18 -> 0 | AQ36: ='G2'!W18 -> 0 | AR36: ='G2'!X18 -> 0 | AS36: ='G2'!Y18 -> 0 | AT36: ='G2'!Z18 -> 0 | AU36: ='G2'!AA18 -> 0 | AV36: ='G2'!AB18 -> 0 | AW36: ='G2'!AC18 -> 0 | AX36: ='G2'!AD18 -> 0 | ... BB36: ='G2'!AH18 -> 0 | BD36: ='G2'!AI18 -> 0 | BE36: ='G2'!AJ18 -> 0 | BF36: ='G2'!AK18 -> 0 | BG36: ='G2'!AL18 -> 0 | BH36: ='G2'!AM18 -> 0 | BI36: ='G2'!AN18 -> 0 | BJ36: ='G2'!AO18 -> 0 | BK36: ='G2'!AP18 -> 0 | ... BO36: ='G2'!AT18 -> 0 | BQ36: ='G2'!AU18 -> 0 | BR36: ='G2'!AV18 -> 0 | BS36: ='G2'!AW18 -> 0 | BT36: ='G2'!AX18 -> 137241.79 | BU36: ='G2'!AY18 -> 0 | BV36: ='G2'!AZ18 -> 0 | BW36: ='G2'!BA18 -> 0 | BX36: ='G2'!BB18 -> 0 | ... CB36: ='G2'!BF18 -> 0
C37: Fee MN | D37: 91243910 | E37: =SUM(G37,I37,K37,M37,O37) -> 100126.13 | G37: =SUM(Q37:AB37) -> 0 | I37: =SUM(AD37:AO37) -> 9249.2833 | K37: =SUM(AQ37:BB37) -> 34606.099 | M37: =SUM(BD37:BO37) -> 36851.884 | O37: =SUM(BQ37:CB37) -> 19418.868 | AI37: ='G2'!P20+'G2'!P21 -> 150.01162 | AJ37: ='G2'!Q20+'G2'!Q21 -> 927.89061 | AK37: ='G2'!R20+'G2'!R21 -> 1529.3421 | AL37: ='G2'!S20+'G2'!S21 -> 1206.6878 | AM37: ='G2'!T20+'G2'!T21 -> 1927.6101 | AN37: ='G2'!U20+'G2'!U21 -> 1419.6506 | AO37: ='G2'!V20+'G2'!V21 -> 2088.0904 | AQ37: ='G2'!W20+'G2'!W21 -> 1216.4791 | AR37: ='G2'!X20+'G2'!X21 -> 4157.6221 | AS37: ='G2'!Y20+'G2'!Y21 -> 3088.5193 | AT37: ='G2'!Z20+'G2'!Z21 -> 5075.98 | AU37: ='G2'!AA20+'G2'!AA21 -> 2713.5073 | AV37: ='G2'!AB20+'G2'!AB21 -> 4501.4779 | AW37: ='G2'!AC20+'G2'!AC21 -> 2713.5073 | AX37: ='G2'!AD20+'G2'!AD21 -> 2232.1812 | ... BB37: ='G2'!AH20+'G2'!AH21 -> 2219.5119 | BD37: ='G2'!AI20+'G2'!AI21 -> 3333.9751 | BE37: ='G2'!AJ20+'G2'!AJ21 -> 2333.1532 | BF37: ='G2'!AK20+'G2'!AK21 -> 5866.607 | BG37: ='G2'!AL20+'G2'!AL21 -> 3012.004 | BH37: ='G2'!AM20+'G2'!AM21 -> 2913.1157 | BI37: ='G2'!AN20+'G2'!AN21 -> 5353.4763 | BJ37: ='G2'!AO20+'G2'!AO21 -> 2913.1157 | BK37: ='G2'!AP20+'G2'!AP21 -> 2292.7176 | ... BO37: ='G2'!AT20+'G2'!AT21 -> 2221.4241 | BQ37: ='G2'!AU20+'G2'!AU21 -> 12241.344 | BR37: ='G2'!AV20+'G2'!AV21 -> 2413.9062 | BS37: ='G2'!AW20+'G2'!AW21 -> 2880.5472 | BT37: ='G2'!AX20+'G2'!AX21 -> 1883.0702 | BU37: ='G2'!AY19 -> 0 | BV37: ='G2'!AZ19 -> 0 | BW37: ='G2'!BA19 -> 0 | BX37: ='G2'!BB19 -> 0 | BY37: ='G2'!BC19 -> 0 | BZ37: ='G2'!BD19 -> 0 | CA37: ='G2'!BE19 -> 0 | CB37: ='G2'!BF19 -> 0
E40: =E4 -> 6744916.6 | G40: =G4 -> 228189.96 | I40: =I4 -> 476667.45 | K40: =K4 -> 1674600.4 | M40: =M4 -> 2034249.7 | O40: =O4 -> 2331209
C44: MN | E44: =+G44+I44+K44+M44+O44 -> 1863094.6 | G44: =+G37+G28+G23+G7+G21+G12 -> 157307.98 | I44: =+I37+I28+I23+I7+I21+I12+I19 -> 403384.93 | K44: =+K7+K12+K21+K23+K28+K31+K35+K37 -> 518252.16 | M44: =+M7+M12+M21+M23+M28+M31+M35+M37 -> 553890.14 | O44: =+O7+O12+O21+O23+O28+O31+O35+O37 -> 230259.4
C45: ME | E45: =+G45+I45+K45+M45+O45 -> 4864634.7 | G45: =+G36+G32+G30+G29+G24+G20+G10+G34+G13+G8 -> 61925.39 | I45: =+I36+I32+I30+I29+I24+I20+I10+I34+I13+I8 -> 65051.892 | K45: =+K8+K13+K20+K24+K25+K26+K27+K29+K30+K32+K33+K34+K36 -> 1156348.2 | M45: =+M8+M13+M20+M24+M25+M26+M27+M29+M30+M32+M33+M34+M36 -> 1480359.6 | O45: =+O8+O13+O20+O24+O25+O26+O27+O29+O30+O32+O33+O34+O36 -> 2100949.6
E46: =+E44+E45 -> 6727729.4 | G46: =+G44+G45 -> 219233.37 | I46: =+I44+I45 -> 468436.82 | K46: =+K44+K45 -> 1674600.4 | M46: =+M44+M45 -> 2034249.7 | O46: =+O44+O45 -> 2331209

Sheet Hoja4
A1: PROGRAMA | D1: 2024 | F1: 2025 | L1: 2024 | M1: REAL | N1: 2025
D2: TOTAL AÑO | F2: TOTAL AÑO | L2: TOTAL AÑO | N2: TOTAL AÑO | P2: DIFERENCIA
A3: Exploración Internacional Otros Países | D3: 226681.02 | F3: 1389013.9 | I3: Exploración Internacional Otros Países | L3: 226879.95 | N3: 414531.47 | P3: =N3-F3 -> -974482.45
A4: Metalotectos de Interés Item I | D4: 226681.02 | F4: 634159.56 | I4: Metalotectos de Interés Item I | L4: 226879.95 | N4: 127714.39 | P4: =N4-F4 -> -506445.17
A5: Geología MN | B5: 91243110 | D5: 113532.73 | F5: 112091.08 | I5: Geología MN | J5: 91243110 | L5: 114687.36 | N5: 144019.86 | P5: =N5-F5 -> 31928.78
A6: Geología ME | B6: 91243120 | D6: 59999.071 | F6: 477383.66 | I6: Geología ME | J6: 91243120 | L6: 59933.249 | N6: 11188.156 | P6: =N6-F6 -> -466195.51
A7: Geoquímica ME | B7: 91243220 | D7: 0 | F7: 0 | I7: Geoquímica ME | J7: 91243220 | L7: 0 | N7: 0 | P7: =N7-F7 -> 0
A8: Geofísica ME | B8: 91243310 | D8: 0 | F8: 0 | I8: Geofísica ME | J8: 91243310 | L8: 0 | N8: 0 | P8: =N8-F8 -> 0
A9: Sondajes ME | B9: 91243510 | D9: 0 | F9: 0 | I9: Sondajes ME | J9: 91243510 | L9: 0 | N9: 0 | P9: =N9-F9 -> 0
A10: Logística MN | B10: 91243520 | D10: 44418.162 | F10: 1260.515 | I10: Logística MN | J10: 91243520 | L10: 34704.318 | N10: -33871.417 | P10: =N10-F10 -> -35131.932
A11: Logística ME | B11: 91243530 | D11: 173.63333 | F11: 0 | I11: Logística ME | J11: 91243530 | L11: 174.72702 | N11: -1784.7809 | P11: =N11-F11 -> -1784.7809
A12: Propiedad Minera ME | B12: 91243610 | D12: 0 | F12: 0 | I12: Propiedad Minera ME | J12: 91243610 | L12: 0 | N12: 0 | P12: =N12-F12 -> 0
A13: Medio Ambiente MN | B13: 91243620 | D13: 0 | F13: 0 | I13: Medio Ambiente MN | J13: 91243620 | L13: 8956.5833 | N13: 0 | P13: =N13-F13 -> 0
A14: Medio Ambiente ME | B14: 91243630 | D14: 0 | F14: 0 | I14: Medio Ambiente ME | J14: 91243630 | L14: 0 | N14: 0 | P14: =N14-F14 -> 0
A15: Seguridad ME | B15: 91243640 | D15: 0 | F15: 0 | I15: Seguridad ME | J15: 91243640 | L15: 0 | N15: 0 | P15: =N15-F15 -> 0
A16: Comunidades ME | B16: 91243650 | D16: 0 | F16: 0 | I16: Comunidades ME | J16: 91243650 | L16: 0 | N16: 0 | P16: =N16-F16 -> 0
... A19: Fee MN | B19: 91243910 | D19: 8557.4204 | F19: 18774.25 | I19: Fee MN | J19: 91243910 | L19: 8423.7101 | N19: 5150.254 | P19: =N19-F19 -> -13623.996
A20: Metalotectos de Interés Item II | D20: 0 | F20: 754854.36 | I20: Metalotectos de Interés Item II | L20: 0 | N20: 286817.08 | P20: =N20-F20 -> -468037.28
A21: Geología MN | B21: 91243110 | D21: 0 | F21: 251050.27 | I21: Geología MN | J21: 91243110 | L21: 0 | N21: 166903.83 | P21: =N21-F21 -> -84146.434
A22: Geología ME | B22: 91243120 | D22: 0 | F22: 165014.41 | I22: Geología ME | J22: 91243120 | L22: 0 | N22: 52837.154 | P22: =N22-F22 -> -112177.26
A23: Geoquímica ME | B23: 91243220 | D23: 0 | F23: 0 | I23: Geoquímica ME | J23: 91243220 | L23: 0 | N23: 0 | P23: =N23-F23 -> 0
A24: Geofísica ME | B24: 91243310 | D24: 0 | F24: 0 | I24: Geofísica ME | J24: 91243310 | L24: 0 | N24: 0 | P24: =N24-F24 -> 0
A25: Sondajes ME | B25: 91243510 | D25: 0 | F25: 0 | I25: Sondajes ME | J25: 91243510 | L25: 0 | N25: 0 | P25: =N25-F25 -> 0
A26: Logística MN | B26: 91243520 | D26: 0 | F26: 192194.54 | I26: Logística MN | J26: 91243520 | L26: 0 | N26: 57803.922 | P26: =N26-F26 -> -134390.62
A27: Logística ME | B27: 91243530 | D27: 0 | F27: 0 | I27: Logística ME | J27: 91243530 | L27: 0 | N27: 0 | P27: =N27-F27 -> 0
A28: Propiedad Minera ME | B28: 91243610 | D28: 0 | F28: 63954.498 | I28: Propiedad Minera ME | J28: 91243610 | L28: 0 | N28: 0 | P28: =N28-F28 -> -63954.498
A29: Medio Ambiente MN | B29: 91243620 | D29: 0 | F29: 0 | I29: Medio Ambiente MN | J29: 91243620 | L29: 0 | N29: 0 | P29: =N29-F29 -> 0
A30: Medio Ambiente ME | B30: 91243630 | D30: 0 | F30: 0 | I30: Medio Ambiente ME | J30: 91243630 | L30: 0 | N30: 0 | P30: =N30-F30 -> 0
A31: Seguridad ME | B31: 91243640 | D31: 0 | F31: 0 | I31: Seguridad ME | J31: 91243640 | L31: 0 | N31: 0 | P31: =N31-F31 -> 0
A32: Comunidades ME | B32: 91243650 | D32: 0 | F32: 19766.69 | I32: Comunidades ME | J32: 91243650 | L32: 0 | N32: 0 | P32: =N32-F32 -> -19766.69
... A35: Fee MN | B35: 91243910 | D35: 0 | F35: 22227.918 | I35: Fee MN | J35: 91243910 | L35: 0 | N35: 9272.169 | P35: =N35-F35 -> -12955.749

Sheet REPORTE GEX
D2: GASTO MENSUAL PESOS CHILENOS $ | R2: GASTO MENSUAL DOLARES $ (dólar corriente) | AF2: GASTO MENSUAL MILES DE DOLARES BASE $
D4: 46053 | E4: 46081 | F4: 46112 | G4: 46142 | H4: 46173 | I4: 46203 | J4: 46234 | K4: 46265 | L4: 46295 | M4: 46326 | N4: 46356 | O4: 46387 | P4: TOTAL PESOS $ | R4: 44927 | S4: 44958 | T4: 44986 | U4: 45017 | V4: 45047 | W4: 45078 | X4: 45108 | Y4: 45139 | Z4: 45170 | AA4: 45200 | AB4: 45231 | AC4: 45261 | AD4: TOTAL US$ | AF4: 44957 | AG4: Incurrido | AH4: Gasto Sap | AI4: Total Enero | AJ4: Ptto Ene | AK4: Cumpl. | AM4: 44985 | AN4: Incurrido | AO4: Gasto SAP | AP4: Total Febrero | AQ4: Ptto Feb | AR4: Cumpl. | AT4: 45016 | AU4: Incurrido | AV4: Gasto SAP | AW4: Total Marzo | AX4: Ptto Mar | AY4: Cumpl. | BA4: 45046 | BB4: Incurrido | BC4: Gasto SAP | BD4: Total Abril | BE4: Ptto Abr | BF4: Cumpl. | BH4: 45077 | BI4: Incurrido | BJ4: Gasto SAP | BK4: Total Mayo | BL4: Ptto May | BM4: Cumpl. | BO4: 45107 | BP4: Incurrido | BQ4: Gasto SAP | BR4: Total Junio | BS4: Ptto Jun | BT4: Cumpl. | BV4: 45137 | BW4: Incurrido | BX4: Gasto SAP | BY4: Total Julio | BZ4: Ptto Jul | CA4: Cumpl. | CC4: 45169 | CD4: Incurrido | CE4: Gasto SAP | CF4: Total Agosto | CG4: Ptto Ago | CH4: Cumpl. | CJ4: 45199 | CK4: Incurrido | CL4: Gasto SAP | CM4: Total Septiembre | CN4: Ptto Sept | CO4: Cumpl. | CQ4: 45230 | CR4: Incurrido | CS4: Gasto SAP | CT4: Total Octubre | CU4: Ptto Oct | CV4: Cumpl. | CX4: 45260 | CY4: Incurrido | CZ4: Gasto SAP | DA4: Total Noviembre | DB4: Ptto Nov | DC4: Cumpl. | DE4: 45291 | DF4: Incurrido | DG4: Gasto SAP | DH4: Total Diciembre | DI4: Ptto Dic | DJ4: Cumpl.
B5: APIS 20224 | R5: =826.34*1000 -> 826340 | S5: =798.26*1000 -> 798260 | T5: =809.5*1000 -> 809500 | U5: =809.5*1000 -> 809500 | V5: 712260 | W5: 726540 | X5: 750440 | Y5: 953710 | Z5: 783630 | AA5: 813950 | AB5: 812620 | AC5: 849120 | AF5: =#REF! -> #REF! | AG5: =#REF! -> #REF! | AK5: % | AM5: =#REF! -> #REF! | AN5: =#REF! -> #REF! | AR5: % | AT5: =#REF! -> #REF! | AU5: =#REF! -> #REF! | AY5: % | BA5: =#REF! -> #REF! | BB5: =#REF! -> #REF! | BF5: % | BM5: % | BT5: % | CA5: % | CH5: % | CO5: % | CV5: % | CX5: 1 | DC5: % | DE5: 1 | DJ5: %
